Workbook
Name CAP: Sensitivity!$E$11
Name INTR: Sensitivity!$E$10
Name Lacs: Assumptions!$D$151
Name OP: Sensitivity!$E$8
Name PC: Sensitivity!$E$6
Name RM: Sensitivity!$E$7
Name SP: Sensitivity!$E$9

Sheet  
A1: Shree Ganesh
C2: IRONWELD ENGINEERING PVT. LTD | D2: IRONWELD ENGINEERING PVT. LTD | E2: IRONWELD ENGINEERING PVT. LTD | F2: IRONWELD ENGINEERING PVT. LTD | G2: IRONWELD ENGINEERING PVT. LTD | H2: IRONWELD ENGINEERING PVT. LTD | I2: IRONWELD ENGINEERING PVT. LTD | J2: IRONWELD ENGINEERING PVT. LTD | K2: IRONWELD ENGINEERING PVT. LTD | L2: IRONWELD ENGINEERING PVT. LTD | M2: IRONWELD ENGINEERING PVT. LTD | N2: IRONWELD ENGINEERING PVT. LTD | O2: IRONWELD ENGINEERING PVT. LTD | P2: IRONWELD ENGINEERING PVT. LTD | Q2: IRONWELD ENGINEERING PVT. LTD | R2: IRONWELD ENGINEERING PVT. LTD
C3: Financial Appraisal
C13: FINANCIAL MODEL OF IEPL
C15: Setting up of 3600 TPA Electroforged Steel Grating Manufacturing Facility
C16: at Pimpalgoan Phata , Post Markal ,Tal- Khed Dist.
C17: PUNE -412 105
C22: Greenweld Engineering Pvt. Ltd. (‘GEPL’ or ‘Company’) was incorporated on January 7, 2020, as a private limited company in Pune, Maharashtra. The Company is engaged in Design & Engineering Manufacturing and Supply of quality Electroforged /Manual Gratings, Stair Treads, Clamps & Handrails.
C23: The Company has embarked on a project for manufacturing 3600 TPA of electroforged gratings at a rented facility in Markal, Pune (‘Project’).
C24: The hard cost of the Project is estimated at INR 148.70 Lakh is proposed to be funded at a debt to equity ratio of 1.855 :1. The equity requirement is proposed to be met by fresh infusion of funds from the promoters and Unsecured Loans from the Promoters to the extent of INR 20.00 Lakh. The total debt requirement is to be funded by way of rupee term loans from banks & financial institutions.
C25: The Project is envisaged to commence operations from January 1, 2021. In the meantime ongoing operations are planned to support the Project.
C26: The Company also proposes to raise Working Capital fund based finance of INR 115 Lakh from Banks/Financial Institutions to kick start the operations post commencement.

Sheet Snapshot
C2: IRONWELD ENGINEERING PVT. LTD GREENFIELD PROJECT
M5: INR Lacs
C6: Project Details
C7: Project Cost | E7: ='Project Cost'!C21 -> 178.18624 | H7: Start of Construction | L7: =Assumptions!E6 -> 44044
C8: Means of Finance | H8: Construction Period (months) | L8: =Assumptions!E7 -> 5
C9: Debt | E9: =Assumptions!E35 -> 115 | H9: Completion Date | L9: =Assumptions!E8 -> 44196
C10: Equity | E10: =E11+E12 -> 63.186241 | H10: Commercial production | L10: =Assumptions!E9 -> 44197
C11: Share Capital | E11: =Assumptions!E33 -> 43.186241 | H11: Moratorium (months) | L11: =Assumptions!E45 -> 6
C12: Unsecured Loan | E12: =Assumptions!E34 -> 20 | H12: Repayment Start Date | L12: =Assumptions!E46 -> 44408
C13: Debt Equity Ratio | E13: =Assumptions!E37 -> 1.8200165 | H13: Repayment Ends Date | L13: =Assumptions!E47 -> 46934
C14: Working Capital Borrowing | E14: =WC!E20 -> 78.571222 | H14: No. of Repayments (months) | L14: =Assumptions!E48 -> 84
H15: Door to Door Tenor (years) | L15: =Assumptions!E49 -> 7.9138889
C16: Projected Financials
C17: Particulars | D17: =PL!D4 -> 44286 | E17: =PL!E4 -> 44651 | F17: =PL!F4 -> 45016 | G17: =PL!G4 -> 45382 | H17: =PL!H4 -> 45747 | I17: =PL!I4 -> 46112 | J17: =PL!J4 -> 46477 | K17: =PL!K4 -> 46843 | ... M17: =PL!M4 -> 47573
C18: Installed Capacity (TPA) | D18: =CoP!E7 -> 3600 | E18: =CoP!F7 -> 3600 | F18: =CoP!G7 -> 3600 | G18: =CoP!H7 -> 3600 | H18: =CoP!I7 -> 3600 | I18: =CoP!J7 -> 3600 | J18: =CoP!K7 -> 3600 | K18: =CoP!L7 -> 3600 | ... M18: =CoP!N7 -> 3600
C19: No. of Months of Operation | D19: =CoP!E5 -> 3 | E19: =CoP!F5 -> 12 | F19: =CoP!G5 -> 12 | G19: =CoP!H5 -> 12 | H19: =CoP!I5 -> 12 | I19: =CoP!J5 -> 12 | J19: =CoP!K5 -> 12 | K19: =CoP!L5 -> 12 | ... M19: =CoP!N5 -> 12
C20: Capacity Utilization | D20: =CoP!E9 -> 0.3 | E20: =CoP!F9 -> 0.35 | F20: =CoP!G9 -> 0.45 | G20: =CoP!H9 -> 0.55 | H20: =CoP!I9 -> 0.65 | I20: =CoP!J9 -> 0.75 | J20: =CoP!K9 -> 0.75 | K20: =CoP!L9 -> 0.75 | ... M20: =CoP!N9 -> 0.75
C21: Net Sales | D21: =PL!D10 -> 160.89192 | E21: =PL!E10 -> 984.71646 | F21: =PL!F10 -> 1259.8765 | G21: =PL!G10 -> 1543.6991 | H21: =PL!H10 -> 1827.5216 | I21: =PL!I10 -> 2111.3442 | J21: =PL!J10 -> 2128.6692 | K21: =PL!K10 -> 2128.6692 | ... M21: =PL!M10 -> 2128.6692
C22: EBITDA | D22: =PL!D31 -> 7.4629124 | E22: =PL!E31 -> 82.094516 | F22: =PL!F31 -> 117.18738 | G22: =PL!G31 -> 154.04325 | H22: =PL!H31 -> 190.57715 | I22: =PL!I31 -> 226.76215 | J22: =PL!J31 -> 225.56151 | K22: =PL!K31 -> 219.83007 | ... M22: =PL!M31 -> 206.9934
C23: PBT | D23: =PL!D39 -> -1.3533471 | E23: =PL!E39 -> 46.124405 | F23: =PL!F39 -> 78.416011 | G23: =PL!G39 -> 112.37434 | H23: =PL!H39 -> 146.00913 | I23: =PL!I39 -> 179.29331 | J23: =PL!J39 -> 179.22464 | K23: =PL!K39 -> 175.05587 | ... M23: =PL!M39 -> 164.6381
C24: PAT | D24: =PL!D43 -> -1.3533471 | E24: =PL!E43 -> 34.515815 | F24: =PL!F43 -> 58.680269 | G24: =PL!G43 -> 84.091967 | H24: =PL!H43 -> 109.26155 | I24: =PL!I43 -> 134.16877 | J24: =PL!J43 -> 134.11738 | K24: =PL!K43 -> 130.99781 | ... M24: =PL!M43 -> 123.20198
C25: Cash Accruals | D25: =PL!D46 -> 1.0522074 | E25: =PL!E46 -> 49.194401 | F25: =PL!F46 -> 70.095955 | G25: =PL!G46 -> 94.857866 | H25: =PL!H46 -> 119.48675 | I25: =PL!I46 -> 143.93892 | J25: =PL!J46 -> 143.50245 | K25: =PL!K46 -> 139.94149 | ... M25: =PL!M46 -> 131.62392
C27: EBITDA Margin | D27: =PL!D32 -> 0.046384631 | E27: =PL!E32 -> 0.083368685 | F27: =PL!F32 -> 0.093014975 | G27: =PL!G32 -> 0.099788392 | H27: =PL!H32 -> 0.10428175 | I27: =PL!I32 -> 0.10740179 | J27: =PL!J32 -> 0.10596363 | K27: =PL!K32 -> 0.10327113 | ... M27: =PL!M32 -> 0.097240753
C28: PAT Margin | D28: =PL!D44 -> 0 | E28: =PL!E44 -> 0 | F28: =PL!F44 -> 0 | G28: =PL!G44 -> 0 | H28: =PL!H44 -> 0 | I28: =PL!I44 -> 0 | J28: =PL!J44 -> 0 | K28: =PL!K44 -> 0 | ... M28: =PL!M44 -> 0
C29: DSCR | D29: =Ratio!D14 -> 1.3659852 | E29: =Ratio!E14 -> 2.755873 | F29: =Ratio!F14 -> 3.3141734 | G29: =Ratio!G14 -> 4.5547988 | H29: =Ratio!H14 -> 5.9573709 | I29: =Ratio!I14 -> 7.5550124 | J29: =Ratio!J14 -> 8.0453168 | K29: =Ratio!K14 -> 8.4340941 | ... M29: =Ratio!M14 -> 9.0557497
C30: Average DSCR | D30: =Ratio!D15 -> 0
C31: Minimum DSCR | D31: =Ratio!D16 -> 0
C33: Critical Ratios
C34: Current Ratio > 1.33 | D34: =KFR!D28 -> 1.1216275 | E34: =KFR!E28 -> 1.2775176 | F34: =KFR!F28 -> 1.4604606 | G34: =KFR!G28 -> 1.6677538 | H34: =KFR!H28 -> 1.8888873 | I34: =KFR!I28 -> 2.1180442 | J34: =KFR!J28 -> 2.4531751 | K34: =KFR!K28 -> 2.7830654 | ... M34: =KFR!M28 -> 3.5727391
D35: =KFR!D29 -> 0 | E35: =KFR!E29 -> 0 | F35: =KFR!F29 -> 0 | G35: =KFR!G29 -> 0 | H35: =KFR!H29 -> 0 | I35: =KFR!I29 -> 0 | J35: =KFR!J29 -> 0 | K35: =KFR!K29 -> 0 | ... M35: =KFR!M29 -> 0
C36: Debt Equity Ratio | D36: =KFR!D40 -> 1.8598515 | E36: =KFR!E40 -> 1.0816829 | F36: =KFR!F40 -> 0.57952875 | G36: =KFR!G40 -> 0.31560912 | H36: =KFR!H40 -> 0.17536401 | I36: =KFR!I40 -> 0.096816138 | J36: =KFR!J40 -> 0.052449156 | K36: =KFR!K40 -> 0.02403311 | ... M36: =KFR!M40 -> 3.4252912e-17
C37: TOL/TNW | D37: =KFR!D39 -> 0 | E37: =KFR!E39 -> 0 | F37: =KFR!F39 -> 0 | G37: =KFR!G39 -> 0 | H37: =KFR!H39 -> 0 | I37: =KFR!I39 -> 0 | J37: =KFR!J39 -> 0 | K37: =KFR!K39 -> 0 | ... M37: =KFR!M39 -> 0
C38: FACR | D38: =KFR!D34 -> 1.300785 | E38: =KFR!E34 -> 1.3430219 | F38: =KFR!F34 -> 1.4508059 | G38: =KFR!G34 -> 1.5996505 | H38: =KFR!H34 -> 1.8185396 | I38: =KFR!I34 -> 2.1721298 | J38: =KFR!J34 -> 2.8400223 | K38: =KFR!K34 -> 4.5850695 | ... M38: =KFR!M34 -> 1.8561851e+15
C39: ACR | D39: =KFR!D35 -> 0 | E39: =KFR!E35 -> 0 | F39: =KFR!F35 -> 0 | G39: =KFR!G35 -> 0 | H39: =KFR!H35 -> 0 | I39: =KFR!I35 -> 0 | J39: =KFR!J35 -> 0 | K39: =KFR!K35 -> 0 | ... M39: =KFR!M35 -> 0
C40: Interest Coverage | D40: =KFR!D30 -> 0.78889262 | E40: =KFR!E30 -> 2.7505918 | F40: =KFR!F30 -> 3.6901642 | G40: =KFR!G30 -> 4.5065818 | H40: =KFR!H30 -> 5.1781592 | I40: =KFR!I30 -> 5.7373661 | J40: =KFR!J30 -> 5.8815568 | K40: =KFR!K30 -> 5.9583597 | ... M40: =KFR!M30 -> 6.0046052
C42: Cash Balance | D42: =CF!D21 -> 1.0522074 | E42: =CF!E21 -> 23.288573 | F42: =CF!F21 -> 67.359974 | G42: =CF!G21 -> 135.80107 | H42: =CF!H21 -> 228.86668 | I42: =CF!I21 -> 346.37971 | J42: =CF!J21 -> 474.65847 | K42: =CF!K21 -> 600.14705 | ... M42: =CF!M21 -> 849.72261

Sheet Assumptions
C2: Assumptions
C4: Key Dates
C5: Financial Closure | E5: 44043
C6: Start of Construction | E6: 44044
C7: Construction Period (months) | E7: 5
C8: Completion Date | E8: =EDATE(E6,E7)-1 -> 44196
C9: Commercial production | E9: =E8+1 -> 44197
C10: End of First Year of Operations | E10: =DATE(IF(MONTH(E9)>3,(YEAR(E9)+1),YEAR(E9)),3,31) -> 44286
C11: No. of months of operation in first year | E11: =ROUND(((E10-E9)/30),0) -> 3
C12: Year End of First Year of Construction | E12: =DATE(IF(MONTH(E6)>3,(YEAR(E6)+1),YEAR(E6)),3,31) -> 44286
C13: 1st Quarter Ending after Start of Construction | E13: =EOMONTH(DATE(YEAR(E6),CEILING(MONTH(E6),3),0),1) -> 44104
C14: 1st Quarter Ending after Start of Operation | E14: =EOMONTH(DATE(YEAR(E9),CEILING(MONTH(E9),3),0),1) -> 44286
C16: Capex Schedule | E16: =EOMONTH(E6,0) -> 44074 | F16: =EOMONTH(E16,1) -> 44104 | G16: =EOMONTH(F16,1) -> 44135 | H16: =EOMONTH(G16,1) -> 44165 | I16: =EOMONTH(H16,1) -> 44196
C17: Land and Site Development | D17: =SUM(E17:I17) -> 1 | E17: 0.8 | F17: 0.2 | G17: 0 | H17: 0 | I17: =1-SUM(E17:H17) -> 0
C18: Factory Building | D18: =SUM(E18:I18) -> 1 | E18: 0.3 | F18: 0.3 | G18: 0.2 | H18: 0.2 | I18: =1-SUM(E18:H18) -> 0
C19: Non-Factory Building | D19: =SUM(E19:I19) -> 1 | E19: 0.3 | F19: 0.3 | G19: 0.2 | H19: 0.2 | I19: =1-SUM(E19:H19) -> 0
C20: Plant & Machinery | D20: =SUM(E20:I20) -> 1 | E20: 0.2 | F20: 0.4 | G20: 0.1 | H20: 0.3 | I20: =1-SUM(E20:H20) -> 0
C21: Utilities & Electrical Equipments | D21: =SUM(E21:I21) -> 1 | E21: 0.2 | F21: 0.2 | G21: 0.2 | H21: 0.2 | I21: =1-SUM(E21:H21) -> 0.2
C22: Misc Fixed Assets | D22: =SUM(E22:I22) -> 1 | E22: 0.2 | F22: 0.2 | G22: 0.2 | H22: 0.2 | I22: =1-SUM(E22:H22) -> 0.2
C23: Vehicle | D23: =SUM(E23:I23) -> 1 | E23: 0 | F23: 0 | G23: 0 | H23: 0.5 | I23: =1-SUM(E23:H23) -> 0.5
C24: Computer | D24: =SUM(E24:I24) -> 1 | E24: 0 | F24: 0 | G24: 0.2 | H24: 0.3 | I24: =1-SUM(E24:H24) -> 0.5
C25: Furniture | D25: =SUM(E25:I25) -> 1 | E25: 0 | F25: 0 | G25: 0.2 | H25: 0.3 | I25: =1-SUM(E25:H25) -> 0.5
C26: Preliminary & Preoperative Expenses | D26: =SUM(E26:I26) -> 1 | E26: 0.2 | F26: 0.2 | G26: 0.2 | H26: 0.2 | I26: =1-SUM(E26:H26) -> 0.2
C27: Contingency | D27: =SUM(E27:I27) -> 1 | E27: 0 | F27: 0 | G27: 0 | H27: 0 | I27: =1-SUM(E27:H27) -> 1
C28: Margin Money for Working Capital | D28: =SUM(E28:I28) -> 1 | E28: 0 | F28: 0 | G28: 0 | H28: 0 | I28: =1-SUM(E28:H28) -> 1
C30: Contingency | D30: 0.015
C32: Means of Finance | E32: INR Lacs
C33: Equity | E33: ='Project Cost'!C21-Assumptions!E35-Assumptions!E34 -> 43.186241
C34: Unsecured Loan | E34: 20
C35: Term Loan | E35: 115
C36: Total | E36: =SUM(E33:E35) -> 178.18624
C37: D/E Ratio | E37: =(E35)/(E33+E34) -> 1.8200165
C38: %Debt | E38: =E37/(1+E37)*100% -> 0.64539214
C40: Upfront Equity | E40: 0.1
C42: Term Loan Assumptions
C43: Effective Interest Rate | E43: =10%+INTR -> 0.1
C44: Upfront Fee | E44: 0
C45: Moratorium (months) | E45: 6
C46: Repayment Start Date | E46: =EOMONTH(EDATE(E9,E45),0) -> 44408
C47: Repayment Ends Date | E47: =EOMONTH(E46,E48-1) -> 46934
...

Sheet Project Cost
B2: Project Cost
J3: Soft Cost Allocation
B4: Particulars | C4: Amount | K4: =C14+C16+C18 -> 5.4958333
B5: Land and Site Development | C5: =D27*(1+PC) -> 9.5 | J5: =C5/SUM($C$5:$C$13) -> 0.064846416 | K5: =$K$4*J5 -> 0.3563851 | L5: =C5+K5 -> 9.8563851
B6: Factory Building | C6: =D32*(1+PC) -> 0 | J6: =C6/SUM($C$5:$C$13) -> 0 | K6: =$K$4*J6 -> 0 | L6: =C6+K6 -> 0
B7: Non-Factory Building | C7: =D37*(1+PC) -> 0 | J7: =C7/SUM($C$5:$C$13) -> 0 | K7: =$K$4*J7 -> 0 | L7: =C7+K7 -> 0
B8: Plant & Machinery | C8: =E55*(1+PC) -> 120 | J8: =C8/SUM($C$5:$C$13) -> 0.81911263 | K8: =$K$4*J8 -> 4.5017065 | L8: =C8+K8 -> 124.50171
B9: Utilities & Electrical Equipments | C9: =E60*(1+PC) -> 14 | J9: =C9/SUM($C$5:$C$13) -> 0.09556314 | K9: =$K$4*J9 -> 0.52519909 | L9: =C9+K9 -> 14.525199
B10: Misc Fixed Assets | C10: =E64*(1+PC) -> 0 | J10: =C10/SUM($C$5:$C$13) -> 0 | K10: =$K$4*J10 -> 0 | L10: =C10+K10 -> 0
B11: Vehicle | C11: =E68*(1+PC) -> 0 | J11: =C11/SUM($C$5:$C$13) -> 0 | K11: =$K$4*J11 -> 0 | L11: =C11+K11 -> 0
B12: Computer | C12: =E72*(1+PC) -> 1 | J12: =C12/SUM($C$5:$C$13) -> 0.0068259386 | K12: =$K$4*J12 -> 0.037514221 | L12: =C12+K12 -> 1.0375142
B13: Furniture | C13: =E76*(1+PC) -> 2 | J13: =C13/SUM($C$5:$C$13) -> 0.013651877 | K13: =$K$4*J13 -> 0.075028441 | L13: =C13+K13 -> 2.0750284
B14: Contingency | C14: =SUM(C5:C13)*Assumptions!D30 -> 2.1975 | L14: =SUM(L5:L13) -> 151.99583
B15: Total Hard Cost | C15: =SUM(C5:C14) -> 148.6975 | K15: Check | L15: =L14+C17-C21 -> 0
B16: Preliminery & Pre Operative Expenses | C16: =D82 -> 0.5
B17: Margin Money for Working Capital | C17: =WC!E18 -> 26.190407
B18: Interest During Construction | C18: ='Capex, Debt'!C114 -> 2.7983333
B19: Total Soft Cost | C19: =SUM(C16:C18) -> 29.488741
B21: Total Project Cost | C21: =C15+C19 -> 178.18624
B23: Land & Site Development | D23: INR Lacs
B25: Deposit for the Rented facilities | D25: 4.5
B26: Site Development | D26: 5
D27: =D25+D26 -> 9.5
B29: Factory Building | D29: INR Lacs
B31: Factory Building | D31: 0
D32: =D31 -> 0
B34: Non-Factory Building | D34: INR Lacs
B36: Non-Factory Building | D36: 0
D37: =D36 -> 0
B39: Plant & Machinery | C39: Qty | D39: Supplier | E39: INR Lacs
B41: Electroforged Grating welding Unit -400 KVA  Bearing bar feeding mechanism-for forward feeding of 40x 5 to 60x100 MS. Flat smoothly at the adjustment of 30mm to 100mm space. Capacity – 250 Mt/Month  Conveyor for exit grating panel of size of 1mtr x 6mtr  Cropping m/c to shear the 8mm dia. of twisted or round bar at the speed of 30 stroke/min. | C41: 1 | D41: Aditya Mech. | E41: 70
B42: Circular Cutting m/c to cut the M.S. grating panel of size max. of 8mm x100mm flat at the speed of 1mtr/min. | C42: 2 | D42: Dattatraya Enterprises | E42: 14
B43: Air screw compressor 50 CFM | C43: 1 | D43: Atlas Capco | E43: 2
B44: Water Chilling Plant 5MT | C44: 1 | D44: Bhagwan | E44: 4
B45: E.O.T. Crane 3Ton -20mtr span double gurder ,10mtrs H. | C45: 1 | D45: Microtek | E45: 9
B46: Jib crane with 2 MT Hoist | C46: 3 | E46: 6
B47: Hydraulic Stamping Machine 50T ( Hard Punch) | C47: 1 | D47: Hydrotek | E47: 3
B48: Cutting Wheel Sharpening Machine | C48: 1 | D48: Fabtech | E48: 2
B49: Material handling Trolley’s & Crane | C49: 2 | D49: GBM | E49: 2
B50: Bench Drilling Machine | C50: 1 | D50: Jwala | E50: 2
...

Sheet Capex, Debt
B2: Capital Expenditure
B4: Capex - Monthly | D4: Till | E4: =DATE(IF(MONTH(E5)>3,YEAR(E5)+1,YEAR(E5)),3,31) -> 44286 | F4: =DATE(IF(MONTH(F5)>3,YEAR(F5)+1,YEAR(F5)),3,31) -> 44286 | G4: =DATE(IF(MONTH(G5)>3,YEAR(G5)+1,YEAR(G5)),3,31) -> 44286 | H4: =DATE(IF(MONTH(H5)>3,YEAR(H5)+1,YEAR(H5)),3,31) -> 44286 | I4: =DATE(IF(MONTH(I5)>3,YEAR(I5)+1,YEAR(I5)),3,31) -> 44286 | J4: TOTAL
D5: =EOMONTH(E5,-2) -> 44012 | E5: =Assumptions!E16 -> 44074 | F5: =Assumptions!F16 -> 44104 | G5: =Assumptions!G16 -> 44135 | H5: =Assumptions!H16 -> 44165 | I5: =Assumptions!I16 -> 44196
B6: Land and Site Development | C6: ='Project Cost'!C5 -> 9.5 | E6: =$C$6*Assumptions!E17 -> 7.6 | F6: =$C$6*Assumptions!F17 -> 1.9 | G6: =$C$6*Assumptions!G17 -> 0 | H6: =$C$6*Assumptions!H17 -> 0 | I6: =$C$6*Assumptions!I17 -> 0 | J6: =SUM(E6:I6) -> 9.5 | K6: =IF(J6=C6,"OK","ERROR") -> OK
B7: Factory Building | C7: ='Project Cost'!C6 -> 0 | K7: =IF(J7=C7,"OK","ERROR") -> OK
B8: Non-Factory Building | C8: ='Project Cost'!C7 -> 0 | K8: =IF(J8=C8,"OK","ERROR") -> OK
B9: Plant & Machinery | C9: ='Project Cost'!C8 -> 120 | E9: =$C$9*Assumptions!E20 -> 24 | F9: =$C$9*Assumptions!F20 -> 48 | G9: =$C$9*Assumptions!G20 -> 12 | H9: =$C$9*Assumptions!H20 -> 36 | I9: =$C$9*Assumptions!I20 -> 0 | J9: =SUM(E9:I9) -> 120 | K9: =IF(J9=C9,"OK","ERROR") -> OK
B10: Utilities & Electrical Equipments | C10: ='Project Cost'!C9 -> 14 | E10: =$C$10*Assumptions!E21 -> 2.8 | F10: =$C$10*Assumptions!F21 -> 2.8 | G10: =$C$10*Assumptions!G21 -> 2.8 | H10: =$C$10*Assumptions!H21 -> 2.8 | I10: =$C$10*Assumptions!I21 -> 2.8 | J10: =SUM(E10:I10) -> 14 | K10: =IF(J10=C10,"OK","ERROR") -> OK
B11: Misc Fixed Assets | C11: ='Project Cost'!C10 -> 0 | K11: =IF(J11=C11,"OK","ERROR") -> OK
B12: Vehicle | C12: ='Project Cost'!C11 -> 0 | K12: =IF(J12=C12,"OK","ERROR") -> OK
B13: Computer | C13: ='Project Cost'!C12 -> 1 | E13: =$C$13*Assumptions!E24 -> 0 | F13: =$C$13*Assumptions!F24 -> 0 | G13: =$C$13*Assumptions!G24 -> 0.2 | H13: =$C$13*Assumptions!H24 -> 0.3 | I13: =$C$13*Assumptions!I24 -> 0.5 | J13: =SUM(E13:I13) -> 1 | K13: =IF(J13=C13,"OK","ERROR") -> OK
B14: Furniture | C14: ='Project Cost'!C13 -> 2 | E14: =$C$14*Assumptions!E25 -> 0 | F14: =$C$14*Assumptions!F25 -> 0 | G14: =$C$14*Assumptions!G25 -> 0.4 | H14: =$C$14*Assumptions!H25 -> 0.6 | I14: =$C$14*Assumptions!I25 -> 1 | J14: =SUM(E14:I14) -> 2 | K14: =IF(J14=C14,"OK","ERROR") -> OK
B15: Contingency | C15: ='Project Cost'!C14 -> 2.1975 | E15: =$C$15*Assumptions!E27 -> 0 | F15: =$C$15*Assumptions!F27 -> 0 | G15: =$C$15*Assumptions!G27 -> 0 | H15: =$C$15*Assumptions!H27 -> 0 | I15: =$C$15*Assumptions!I27 -> 2.1975 | J15: =SUM(E15:I15) -> 2.1975 | K15: =IF(J15=C15,"OK","ERROR") -> OK
B16: Preliminary & Preoperative Expenses | C16: ='Project Cost'!C16 -> 0.5 | E16: =$C$16*Assumptions!E26 -> 0.1 | F16: =$C$16*Assumptions!F26 -> 0.1 | G16: =$C$16*Assumptions!G26 -> 0.1 | H16: =$C$16*Assumptions!H26 -> 0.1 | I16: =$C$16*Assumptions!I26 -> 0.1 | J16: =SUM(E16:I16) -> 0.5 | K16: =IF(J16=C16,"OK","ERROR") -> OK
B17: Margin Money for Working Capital | C17: ='Project Cost'!C17 -> 26.190407 | E17: =$C$17*Assumptions!E28 -> 0 | F17: =$C$17*Assumptions!F28 -> 0 | G17: =$C$17*Assumptions!G28 -> 0 | H17: =$C$17*Assumptions!H28 -> 0 | I17: =$C$17*Assumptions!I28 -> 26.190407 | J17: =SUM(E17:I17) -> 26.190407 | K17: =IF(J17=C17,"OK","ERROR") -> OK
B18: Interest During Construction | C18: ='Project Cost'!C18 -> 2.7983333 | E18: =E71 -> 0.11979167 | F18: =F71 -> 0.40729167 | G18: =G71 -> 0.62291667 | H18: =H71 -> 0.75229167 | I18: =I71 -> 0.89604167 | J18: =SUM(E18:I18) -> 2.7983333 | K18: =IF(J18=C18,"OK","ERROR") -> OK
B19: Total Project Cost | C19: =SUM(C6:C18) -> 178.18624 | D19: =SUM(D6:D18) -> 0 | E19: =SUM(E6:E18) -> 34.619792 | F19: =SUM(F6:F18) -> 53.207292 | G19: =SUM(G6:G18) -> 16.122917 | H19: =SUM(H6:H18) -> 40.552292 | I19: =SUM(I6:I18) -> 33.683949 | J19: =SUM(J6:J18) -> 178.18624
C20: =IF(C19='Project Cost'!C21,"Ok","ERROR") -> Ok
B23: Capex - Monthly | D23: Till | E23: =DATE(IF(MONTH(E24)>3,YEAR(E24)+1,YEAR(E24)),3,31) -> 44286 | F23: =DATE(IF(MONTH(F24)>3,YEAR(F24)+1,YEAR(F24)),3,31) -> 44286 | G23: =DATE(IF(MONTH(G24)>3,YEAR(G24)+1,YEAR(G24)),3,31) -> 44286 | H23: =DATE(IF(MONTH(H24)>3,YEAR(H24)+1,YEAR(H24)),3,31) -> 44286 | I23: =DATE(IF(MONTH(I24)>3,YEAR(I24)+1,YEAR(I24)),3,31) -> 44286 | J23: TOTAL
D24: =EOMONTH(E24,-2) -> 44012 | E24: =E5 -> 44074 | F24: =F5 -> 44104 | G24: =G5 -> 44135 | H24: =H5 -> 44165 | I24: =I5 -> 44196
B26: Total Funds Requirement | C26: =C19 -> 178.18624 | D26: =D19 -> 0 | E26: =E19 -> 34.619792 | F26: =F19 -> 53.207292 | G26: =G19 -> 16.122917 | H26: =H19 -> 40.552292 | I26: =I19 -> 33.683949 | J26: =SUM(D26:I26) -> 178.18624
B28: Upfront Equity | C28: =Assumptions!E33*Assumptions!E40 -> 4.3186241
B30: Upfront Equity Drawl | E30: =C28 -> 4.3186241
B31: Net Drawl Required | E31: =E26-E33-E30 -> 1.5511676 | F31: =F26-F33-F30 -> 12.957292 | G31: =G26-G33-G30 -> 4.6229167 | H31: =H26-H33-H30 -> 21.002292 | I31: =I26-I33-I30 -> 18.733949 | J31: =SUM(E31:I31) -> 58.867617
B33: Debt | E33: =Assumptions!$E$35*'Capex, Debt'!E37 -> 28.75 | F33: =Assumptions!$E$35*'Capex, Debt'!F37 -> 40.25 | G33: =Assumptions!$E$35*'Capex, Debt'!G37 -> 11.5 | H33: =Assumptions!$E$35*'Capex, Debt'!H37 -> 19.55 | I33: =Assumptions!$E$35*'Capex, Debt'!I37 -> 14.95 | J33: =SUM(E33:I33) -> 115
B34: Equity Drawl | E34: =E31+E30 -> 5.8697917 | F34: =F31+F30 -> 12.957292 | G34: =G31+G30 -> 4.6229167 | H34: =H31+H30 -> 21.002292 | I34: =I31+I30 -> 18.733949 | J34: =SUM(E34:I34) -> 63.186241
B35: Check | C35: =C33+C34-C26 -> -178.18624 | E35: =E33+E34-E26 -> 0 | F35: =F33+F34-F26 -> 0 | G35: =G33+G34-G26 -> 0 | H35: =H33+H34-H26 -> 0 | I35: =I33+I34-I26 -> 0
B37: Debt Drawl % | C37: =SUM(E37:I37) -> 1 | E37: 0.25 | F37: 0.35 | G37: 0.1 | H37: 0.17 | I37: =1-SUM(E37:H37) -> 0.13
B41: Quarterly
B42: FY | C42: Q1 | D42: Q2 | E42: Q3 | F42: Q4 | G42: Total | I42: FY | J42: Apr | K42: May | L42: Jun | M42: Jul | N42: Aug | O42: Sep | P42: Oct | Q42: Nov | R42: Dec | S42: Jan | T42: Feb | U42: Mar | V42: Total
B43: 2021 | C43: =Assumptions!D64 -> 0 | D43: =Assumptions!E64 -> 0 | E43: =Assumptions!F64 -> 0 | F43: =Assumptions!G64 -> 0 | G43: =SUM(C43:F43) -> 0 | I43: =B43 -> 2021 | J43: =C43/3 -> 0 | K43: =J43 -> 0 | L43: =K43 -> 0 | M43: =D43/3 -> 0 | N43: =M43 -> 0 | O43: =N43 -> 0 | P43: =E43/3 -> 0 | Q43: =P43 -> 0 | R43: =Q43 -> 0 | S43: =F43/3 -> 0 | T43: =S43 -> 0 | U43: =T43 -> 0 | V43: =SUM(J43:U43) -> 0
B44: =B43+1 -> 2022 | C44: =Assumptions!D65 -> 0 | D44: =Assumptions!E65 -> 0.03125 | E44: =Assumptions!F65 -> 0.03125 | F44: =Assumptions!G65 -> 0.03125 | G44: =SUM(C44:F44) -> 0.09375 | I44: =B44 -> 2022 | J44: =C44/3 -> 0 | K44: =J44 -> 0 | L44: =K44 -> 0 | M44: =D44/3 -> 0.010416667 | N44: =M44 -> 0.010416667 | O44: =N44 -> 0.010416667 | P44: =E44/3 -> 0.010416667 | Q44: =P44 -> 0.010416667 | R44: =Q44 -> 0.010416667 | S44: =F44/3 -> 0.010416667 | T44: =S44 -> 0.010416667 | U44: =T44 -> 0.010416667 | V44: =SUM(J44:U44) -> 0.09375
B45: =B44+1 -> 2023 | C45: =Assumptions!D66 -> 0.03125 | D45: =Assumptions!E66 -> 0.03125 | E45: =Assumptions!F66 -> 0.03125 | F45: =Assumptions!G66 -> 0.03125 | G45: =SUM(C45:F45) -> 0.125 | I45: =B45 -> 2023 | J45: =C45/3 -> 0.010416667 | K45: =J45 -> 0.010416667 | L45: =K45 -> 0.010416667 | M45: =D45/3 -> 0.010416667 | N45: =M45 -> 0.010416667 | O45: =N45 -> 0.010416667 | P45: =E45/3 -> 0.010416667 | Q45: =P45 -> 0.010416667 | R45: =Q45 -> 0.010416667 | S45: =F45/3 -> 0.010416667 | T45: =S45 -> 0.010416667 | U45: =T45 -> 0.010416667 | V45: =SUM(J45:U45) -> 0.125
B46: =B45+1 -> 2024 | C46: =Assumptions!D67 -> 0.03125 | D46: =Assumptions!E67 -> 0.03125 | E46: =Assumptions!F67 -> 0.03125 | F46: =Assumptions!G67 -> 0.03125 | G46: =SUM(C46:F46) -> 0.125 | I46: =B46 -> 2024 | J46: =C46/3 -> 0.010416667 | K46: =J46 -> 0.010416667 | L46: =K46 -> 0.010416667 | M46: =D46/3 -> 0.010416667 | N46: =M46 -> 0.010416667 | O46: =N46 -> 0.010416667 | P46: =E46/3 -> 0.010416667 | Q46: =P46 -> 0.010416667 | R46: =Q46 -> 0.010416667 | S46: =F46/3 -> 0.010416667 | T46: =S46 -> 0.010416667 | U46: =T46 -> 0.010416667 | V46: =SUM(J46:U46) -> 0.125
B47: =B46+1 -> 2025 | C47: =Assumptions!D68 -> 0.03125 | D47: =Assumptions!E68 -> 0.03125 | E47: =Assumptions!F68 -> 0.03125 | F47: =Assumptions!G68 -> 0.03125 | G47: =SUM(C47:F47) -> 0.125 | I47: =B47 -> 2025 | J47: =C47/3 -> 0.010416667 | K47: =J47 -> 0.010416667 | L47: =K47 -> 0.010416667 | M47: =D47/3 -> 0.010416667 | N47: =M47 -> 0.010416667 | O47: =N47 -> 0.010416667 | P47: =E47/3 -> 0.010416667 | Q47: =P47 -> 0.010416667 | R47: =Q47 -> 0.010416667 | S47: =F47/3 -> 0.010416667 | T47: =S47 -> 0.010416667 | U47: =T47 -> 0.010416667 | V47: =SUM(J47:U47) -> 0.125
B48: =B47+1 -> 2026 | C48: =Assumptions!D69 -> 0.03125 | D48: =Assumptions!E69 -> 0.03125 | E48: =Assumptions!F69 -> 0.03125 | F48: =Assumptions!G69 -> 0.03125 | G48: =SUM(C48:F48) -> 0.125 | I48: =B48 -> 2026 | J48: =C48/3 -> 0.010416667 | K48: =J48 -> 0.010416667 | L48: =K48 -> 0.010416667 | M48: =D48/3 -> 0.010416667 | N48: =M48 -> 0.010416667 | O48: =N48 -> 0.010416667 | P48: =E48/3 -> 0.010416667 | Q48: =P48 -> 0.010416667 | R48: =Q48 -> 0.010416667 | S48: =F48/3 -> 0.010416667 | T48: =S48 -> 0.010416667 | U48: =T48 -> 0.010416667 | V48: =SUM(J48:U48) -> 0.125
B49: =B48+1 -> 2027 | C49: =Assumptions!D70 -> 0.03125 | D49: =Assumptions!E70 -> 0.03125 | E49: =Assumptions!F70 -> 0.03125 | F49: =Assumptions!G70 -> 0.03125 | G49: =SUM(C49:F49) -> 0.125 | I49: =B49 -> 2027 | J49: =C49/3 -> 0.010416667 | K49: =J49 -> 0.010416667 | L49: =K49 -> 0.010416667 | M49: =D49/3 -> 0.010416667 | N49: =M49 -> 0.010416667 | O49: =N49 -> 0.010416667 | P49: =E49/3 -> 0.010416667 | Q49: =P49 -> 0.010416667 | R49: =Q49 -> 0.010416667 | S49: =F49/3 -> 0.010416667 | T49: =S49 -> 0.010416667 | U49: =T49 -> 0.010416667 | V49: =SUM(J49:U49) -> 0.125
B50: =B49+1 -> 2028 | C50: =Assumptions!D71 -> 0.03125 | D50: =Assumptions!E71 -> 0.03125 | E50: =Assumptions!F71 -> 0.03125 | F50: =Assumptions!G71 -> 0.03125 | G50: =SUM(C50:F50) -> 0.125 | I50: =B50 -> 2028 | J50: =C50/3 -> 0.010416667 | K50: =J50 -> 0.010416667 | L50: =K50 -> 0.010416667 | M50: =D50/3 -> 0.010416667 | N50: =M50 -> 0.010416667 | O50: =N50 -> 0.010416667 | P50: =E50/3 -> 0.010416667 | Q50: =P50 -> 0.010416667 | R50: =Q50 -> 0.010416667 | S50: =F50/3 -> 0.010416667 | T50: =S50 -> 0.010416667 | U50: =T50 -> 0.010416667 | V50: =SUM(J50:U50) -> 0.125
B51: =B50+1 -> 2029 | C51: =Assumptions!D72 -> 0.03125 | D51: =Assumptions!E72 -> 0.03125 | E51: =Assumptions!F72 -> 0.03125 | F51: =Assumptions!G72 -> 0.03125 | G51: =SUM(C51:F51) -> 0.125 | I51: =B51 -> 2029 | J51: =C51/3 -> 0.010416667 | K51: =J51 -> 0.010416667 | L51: =K51 -> 0.010416667 | M51: =D51/3 -> 0.010416667 | N51: =M51 -> 0.010416667 | O51: =N51 -> 0.010416667 | P51: =E51/3 -> 0.010416667 | Q51: =P51 -> 0.010416667 | R51: =Q51 -> 0.010416667 | S51: =F51/3 -> 0.010416667 | T51: =S51 -> 0.010416667 | U51: =T51 -> 0.010416667 | V51: =SUM(J51:U51) -> 0.125
B52: =B51+1 -> 2030 | C52: =Assumptions!D73 -> 0.03125 | D52: =Assumptions!E73 -> 0 | E52: =Assumptions!F73 -> 0 | F52: =Assumptions!G73 -> 0 | G52: =SUM(C52:F52) -> 0.03125 | I52: =B52 -> 2030 | J52: =C52/3 -> 0.010416667 | K52: =J52 -> 0.010416667 | L52: =K52 -> 0.010416667 | M52: =D52/3 -> 0 | N52: =M52 -> 0 | O52: =N52 -> 0 | P52: =E52/3 -> 0 | Q52: =P52 -> 0 | R52: =Q52 -> 0 | S52: =F52/3 -> 0 | T52: =S52 -> 0 | U52: =T52 -> 0 | V52: =SUM(J52:U52) -> 0.03125
...

Sheet CoP
B2: Cost of Production
B4: FY Ending | E4: =Assumptions!E82 -> 44286 | F4: =Assumptions!F82 -> 44651 | G4: =Assumptions!G82 -> 45016 | H4: =Assumptions!H82 -> 45382 | I4: =Assumptions!I82 -> 45747 | J4: =Assumptions!J82 -> 46112 | K4: =Assumptions!K82 -> 46477 | L4: =Assumptions!L82 -> 46843 | ... N4: =Assumptions!N82 -> 47573
B5: No. of Months | E5: =Assumptions!E83 -> 3 | F5: =Assumptions!F83 -> 12 | G5: =Assumptions!G83 -> 12 | H5: =Assumptions!H83 -> 12 | I5: =Assumptions!I83 -> 12 | J5: =Assumptions!J83 -> 12 | K5: =Assumptions!K83 -> 12 | L5: =Assumptions!L83 -> 12 | ... N5: =Assumptions!N83 -> 12
B7: Capacity | C7: Ton | E7: =Assumptions!E85 -> 3600 | F7: =Assumptions!F85 -> 3600 | G7: =Assumptions!G85 -> 3600 | H7: =Assumptions!H85 -> 3600 | I7: =Assumptions!I85 -> 3600 | J7: =Assumptions!J85 -> 3600 | K7: =Assumptions!K85 -> 3600 | L7: =Assumptions!L85 -> 3600 | ... N7: =Assumptions!N85 -> 3600
B9: Capacity Utilisation | E9: =Assumptions!E86 -> 0.3 | F9: =Assumptions!F86 -> 0.35 | G9: =Assumptions!G86 -> 0.45 | H9: =Assumptions!H86 -> 0.55 | I9: =Assumptions!I86 -> 0.65 | J9: =Assumptions!J86 -> 0.75 | K9: =Assumptions!K86 -> 0.75 | L9: =Assumptions!L86 -> 0.75 | ... N9: =Assumptions!N86 -> 0.75
B11: Production | C11: Ton | E11: =E7*E9*E5/12 -> 270 | F11: =F7*F9*F5/12 -> 1260 | G11: =G7*G9*G5/12 -> 1620 | H11: =H7*H9*H5/12 -> 1980 | I11: =I7*I9*I5/12 -> 2340 | J11: =J7*J9*J5/12 -> 2700 | K11: =K7*K9*K5/12 -> 2700 | L11: =L7*L9*L5/12 -> 2700 | ... N11: =N7*N9*N5/12 -> 2700
B13: WIP Inventory - Opening | E13: 0 | F13: =E14 -> 45 | G13: =F14 -> 52.5 | H13: =G14 -> 67.5 | I13: =H14 -> 82.5 | J13: =I14 -> 97.5 | K13: =J14 -> 112.5 | L13: =K14 -> 112.5 | M13: =L14 -> 112.5 | N13: =M14 -> 112.5
A14: =Assumptions!D118 -> 0.5 | B14: WIP Inventory - Closing | C14: Ton | E14: =E11/E5*$A$14 -> 45 | F14: =F11/F5*$A$14 -> 52.5 | G14: =G11/G5*$A$14 -> 67.5 | H14: =H11/H5*$A$14 -> 82.5 | I14: =I11/I5*$A$14 -> 97.5 | J14: =J11/J5*$A$14 -> 112.5 | K14: =K11/K5*$A$14 -> 112.5 | L14: =L11/L5*$A$14 -> 112.5 | ... N14: =N11/N5*$A$14 -> 112.5
B16: FG Inventory - Opening | E16: 0 | F16: =E17 -> 22.5 | G16: =F17 -> 26.25 | H16: =G17 -> 33.75 | I16: =H17 -> 41.25 | J16: =I17 -> 48.75 | K16: =J17 -> 56.25 | L16: =K17 -> 56.25 | M16: =L17 -> 56.25 | N16: =M17 -> 56.25
A17: =Assumptions!D119 -> 0.25 | B17: FG Inventory - Closing | C17: Ton | E17: =E11/E5*$A$17 -> 22.5 | F17: =F11/F5*$A$17 -> 26.25 | G17: =G11/G5*$A$17 -> 33.75 | H17: =H11/H5*$A$17 -> 41.25 | I17: =I11/I5*$A$17 -> 48.75 | J17: =J11/J5*$A$17 -> 56.25 | K17: =K11/K5*$A$17 -> 56.25 | L17: =L11/L5*$A$17 -> 56.25 | ... N17: =N11/N5*$A$17 -> 56.25
B19: Sales Quantity | C19: Ton | E19: =E11+E13-E14+E16-E17 -> 202.5 | F19: =F11+F13-F14+F16-F17 -> 1248.75 | G19: =G11+G13-G14+G16-G17 -> 1597.5 | H19: =H11+H13-H14+H16-H17 -> 1957.5 | I19: =I11+I13-I14+I16-I17 -> 2317.5 | J19: =J11+J13-J14+J16-J17 -> 2677.5 | K19: =K11+K13-K14+K16-K17 -> 2700 | L19: =L11+L13-L14+L16-L17 -> 2700 | ... N19: =N11+N13-N14+N16-N17 -> 2700
B21: Raw Material Requirement
B22: Steel | C22: Ton | E22: =E11*Assumptions!$D$90 -> 302.4 | F22: =F11*Assumptions!$D$90 -> 1411.2 | G22: =G11*Assumptions!$D$90 -> 1814.4 | H22: =H11*Assumptions!$D$90 -> 2217.6 | I22: =I11*Assumptions!$D$90 -> 2620.8 | J22: =J11*Assumptions!$D$90 -> 3024 | K22: =K11*Assumptions!$D$90 -> 3024 | L22: =L11*Assumptions!$D$90 -> 3024 | ... N22: =N11*Assumptions!$D$90 -> 3024
B23: (Scrap Generation) | C23: Ton | D23: 0.09 | E23: =E22*$D$23 -> 27.216 | F23: =F22*$D$23 -> 127.008 | G23: =G22*$D$23 -> 163.296 | H23: =H22*$D$23 -> 199.584 | I23: =I22*$D$23 -> 235.872 | J23: =J22*$D$23 -> 272.16 | K23: =K22*$D$23 -> 272.16 | L23: =L22*$D$23 -> 272.16 | ... N23: =N22*$D$23 -> 272.16
B25: Sales of Electroforged Gratings | C25: INR Lacs | E25: =E19*Assumptions!$D$108/Lacs -> 155.925 | F25: =F19*Assumptions!$D$108/Lacs -> 961.5375 | G25: =G19*Assumptions!$D$108/Lacs -> 1230.075 | H25: =H19*Assumptions!$D$108/Lacs -> 1507.275 | I25: =I19*Assumptions!$D$108/Lacs -> 1784.475 | J25: =J19*Assumptions!$D$108/Lacs -> 2061.675 | K25: =K19*Assumptions!$D$108/Lacs -> 2079 | L25: =L19*Assumptions!$D$108/Lacs -> 2079 | ... N25: =N19*Assumptions!$D$108/Lacs -> 2079
B26: Scrap Sales | C26: INR Lacs | E26: =E23*Assumptions!$D$109/Lacs -> 4.96692 | F26: =F23*Assumptions!$D$109/Lacs -> 23.17896 | G26: =G23*Assumptions!$D$109/Lacs -> 29.80152 | H26: =H23*Assumptions!$D$109/Lacs -> 36.42408 | I26: =I23*Assumptions!$D$109/Lacs -> 43.04664 | J26: =J23*Assumptions!$D$109/Lacs -> 49.6692 | K26: =K23*Assumptions!$D$109/Lacs -> 49.6692 | L26: =L23*Assumptions!$D$109/Lacs -> 49.6692 | ... N26: =N23*Assumptions!$D$109/Lacs -> 49.6692
B27: Clamp and Hardware Sales | C27: INR Lacs
B28: Sales | C28: INR Lacs | E28: =SUM(E25:E27) -> 160.89192 | F28: =SUM(F25:F27) -> 984.71646 | G28: =SUM(G25:G27) -> 1259.8765 | H28: =SUM(H25:H27) -> 1543.6991 | I28: =SUM(I25:I27) -> 1827.5216 | J28: =SUM(J25:J27) -> 2111.3442 | K28: =SUM(K25:K27) -> 2128.6692 | L28: =SUM(L25:L27) -> 2128.6692 | ... N28: =SUM(N25:N27) -> 2128.6692
B30: Raw Material Cost | C30: INR Lacs | E30: =E22*Assumptions!$E$90/Lacs -> 110.376 | F30: =F22*Assumptions!$E$90/Lacs -> 515.088 | G30: =G22*Assumptions!$E$90/Lacs -> 662.256 | H30: =H22*Assumptions!$E$90/Lacs -> 809.424 | I30: =I22*Assumptions!$E$90/Lacs -> 956.592 | J30: =J22*Assumptions!$E$90/Lacs -> 1103.76 | K30: =K22*Assumptions!$E$90/Lacs -> 1103.76 | L30: =L22*Assumptions!$E$90/Lacs -> 1103.76 | ... N30: =N22*Assumptions!$E$90/Lacs -> 1103.76
B31: Galv. Charges | C31: INR Lacs | E31: =E11*Assumptions!$F$92/Lacs -> 45.738 | F31: =F11*Assumptions!$F$92/Lacs -> 213.444 | G31: =G11*Assumptions!$F$92/Lacs -> 274.428 | H31: =H11*Assumptions!$F$92/Lacs -> 335.412 | I31: =I11*Assumptions!$F$92/Lacs -> 396.396 | J31: =J11*Assumptions!$F$92/Lacs -> 457.38 | K31: =K11*Assumptions!$F$92/Lacs -> 457.38 | L31: =L11*Assumptions!$F$92/Lacs -> 457.38 | ... N31: =N11*Assumptions!$F$92/Lacs -> 457.38
B32: MSEB Electricity | C32: INR Lacs | E32: =E11*Assumptions!$F$93/Lacs -> 5.184 | F32: =F11*Assumptions!$F$93/Lacs -> 24.192 | G32: =G11*Assumptions!$F$93/Lacs -> 31.104 | H32: =H11*Assumptions!$F$93/Lacs -> 38.016 | I32: =I11*Assumptions!$F$93/Lacs -> 44.928 | J32: =J11*Assumptions!$F$93/Lacs -> 51.84 | K32: =K11*Assumptions!$F$93/Lacs -> 51.84 | L32: =L11*Assumptions!$F$93/Lacs -> 51.84 | ... N32: =N11*Assumptions!$F$93/Lacs -> 51.84
B33: Fabrication Cost | C33: INR Lacs | E33: =E11*Assumptions!$F$94/Lacs -> 8.1 | F33: =F11*Assumptions!$F$94/Lacs -> 37.8 | G33: =G11*Assumptions!$F$94/Lacs -> 48.6 | H33: =H11*Assumptions!$F$94/Lacs -> 59.4 | I33: =I11*Assumptions!$F$94/Lacs -> 70.2 | J33: =J11*Assumptions!$F$94/Lacs -> 81 | K33: =K11*Assumptions!$F$94/Lacs -> 81 | L33: =L11*Assumptions!$F$94/Lacs -> 81 | ... N33: =N11*Assumptions!$F$94/Lacs -> 81
B34: Consumable | C34: INR Lacs | E34: =E11*Assumptions!$F$95/Lacs -> 4.158 | F34: =F11*Assumptions!$F$95/Lacs -> 19.404 | G34: =G11*Assumptions!$F$95/Lacs -> 24.948 | H34: =H11*Assumptions!$F$95/Lacs -> 30.492 | I34: =I11*Assumptions!$F$95/Lacs -> 36.036 | J34: =J11*Assumptions!$F$95/Lacs -> 41.58 | K34: =K11*Assumptions!$F$95/Lacs -> 41.58 | L34: =L11*Assumptions!$F$95/Lacs -> 41.58 | ... N34: =N11*Assumptions!$F$95/Lacs -> 41.58
B35: Testing & Maint | C35: INR Lacs | E35: =E11*Assumptions!$F$96/Lacs -> 2.079 | F35: =F11*Assumptions!$F$96/Lacs -> 9.702 | G35: =G11*Assumptions!$F$96/Lacs -> 12.474 | H35: =H11*Assumptions!$F$96/Lacs -> 15.246 | I35: =I11*Assumptions!$F$96/Lacs -> 18.018 | J35: =J11*Assumptions!$F$96/Lacs -> 20.79 | K35: =K11*Assumptions!$F$96/Lacs -> 20.79 | L35: =L11*Assumptions!$F$96/Lacs -> 20.79 | ... N35: =N11*Assumptions!$F$96/Lacs -> 20.79
B36: Salaries & Wages | C36: INR Lacs | E36: =Assumptions!E102*Assumptions!E83 -> 9.57 | F36: =Assumptions!F102*Assumptions!F83 -> 40.194 | G36: =Assumptions!G102*Assumptions!G83 -> 42.2037 | H36: =Assumptions!H102*Assumptions!H83 -> 44.313885 | I36: =Assumptions!I102*Assumptions!I83 -> 46.529579 | J36: =Assumptions!J102*Assumptions!J83 -> 48.856058 | K36: =Assumptions!K102*Assumptions!K83 -> 51.298861 | L36: =Assumptions!L102*Assumptions!L83 -> 53.863804 | ... N36: =Assumptions!N102*Assumptions!N83 -> 59.384844
B37: Factory Rent | C37: INR Lacs | E37: =Assumptions!D99/12*Assumptions!E83 -> 4.5 | F37: =Assumptions!D99*(1+Assumptions!E99) -> 19.8 | G37: =F37*(1+Assumptions!$E$99) -> 21.78 | H37: =G37*(1+Assumptions!$E$99) -> 23.958 | I37: =H37*(1+Assumptions!$E$99) -> 26.3538 | J37: =I37*(1+Assumptions!$E$99) -> 28.98918 | K37: =J37*(1+Assumptions!$E$99) -> 31.888098 | L37: =K37*(1+Assumptions!$E$99) -> 35.076908 | M37: =L37*(1+Assumptions!$E$99) -> 38.584599 | N37: =M37*(1+Assumptions!$E$99) -> 42.443058
B38: Total Manufacturing Expenses | C38: INR Lacs | E38: =SUM(E30:E37) -> 189.705 | F38: =SUM(F30:F37) -> 879.624 | G38: =SUM(G30:G37) -> 1117.7937 | H38: =SUM(H30:H37) -> 1356.2619 | I38: =SUM(I30:I37) -> 1595.0534 | J38: =SUM(J30:J37) -> 1834.1952 | K38: =SUM(K30:K37) -> 1839.537 | L38: =SUM(L30:L37) -> 1845.2907 | ... N38: =SUM(N30:N37) -> 1858.1779
B39: Manufacturing Cost per Unit | C39: INR per Ton | E39: =E38*Lacs/E11 -> 70261.111 | F39: =F38*Lacs/F11 -> 69811.429 | G39: =G38*Lacs/G11 -> 68999.611 | H39: =H38*Lacs/H11 -> 68498.075 | I39: =I38*Lacs/I11 -> 68164.674 | J39: =J38*Lacs/J11 -> 67933.157 | K39: =K38*Lacs/K11 -> 68130.998 | L39: =L38*Lacs/L11 -> 68344.1 | ... N39: =N38*Lacs/N11 -> 68821.404
B41: WIP Opening | E41: 0 | F41: =E42 -> 25.294 | G41: =F42 -> 29.3208 | H41: =G42 -> 37.25979 | I41: =H42 -> 45.20873 | J41: =I42 -> 53.168446 | K41: =J42 -> 61.139841 | L41: =K42 -> 61.317899 | M41: =L42 -> 61.50969 | N41: =M42 -> 61.716386
B42: WIP Closing | E42: =E14*E39/Lacs*80% -> 25.294 | F42: =F14*F39/Lacs*80% -> 29.3208 | G42: =G14*G39/Lacs*80% -> 37.25979 | H42: =H14*H39/Lacs*80% -> 45.20873 | I42: =I14*I39/Lacs*80% -> 53.168446 | J42: =J14*J39/Lacs*80% -> 61.139841 | K42: =K14*K39/Lacs*80% -> 61.317899 | L42: =L14*L39/Lacs*80% -> 61.50969 | ... N42: =N14*N39/Lacs*80% -> 61.939263
B44: Cost of Production | C44: INR Lacs | E44: =E38+E41-E42 -> 164.411 | F44: =F38+F41-F42 -> 875.5972 | G44: =G38+G41-G42 -> 1109.8547 | H44: =H38+H41-H42 -> 1348.3129 | I44: =I38+I41-I42 -> 1587.0937 | J44: =J38+J41-J42 -> 1826.2238 | K44: =K38+K41-K42 -> 1839.3589 | L44: =L38+L41-L42 -> 1845.0989 | ... N44: =N38+N41-N42 -> 1857.955
B47: Total Expenses per Unit
B49: FG Opening | F49: =E50 -> 15.80875 | G49: =F50 -> 18.3255 | H49: =G50 -> 23.287369 | I49: =H50 -> 28.255456 | J49: =I50 -> 33.230279 | K49: =J50 -> 38.212401 | L49: =K50 -> 38.323687 | M49: =L50 -> 38.443556 | N49: =M50 -> 38.572742
B50: FG Closing | E50: =E17*E39/Lacs -> 15.80875 | F50: =F17*F39/Lacs -> 18.3255 | G50: =G17*G39/Lacs -> 23.287369 | H50: =H17*H39/Lacs -> 28.255456 | I50: =I17*I39/Lacs -> 33.230279 | J50: =J17*J39/Lacs -> 38.212401 | K50: =K17*K39/Lacs -> 38.323687 | L50: =L17*L39/Lacs -> 38.443556 | ... N50: =N17*N39/Lacs -> 38.71204
B52: Cost of Sales | C52: INR Lacs | E52: =E44+E49-E50 -> 148.60225 | F52: =F44+F49-F50 -> 873.08045 | G52: =G44+G49-G50 -> 1104.8928 | H52: =H44+H49-H50 -> 1343.3449 | I52: =I44+I49-I50 -> 1582.1188 | J52: =J44+J49-J50 -> 1821.2417 | K52: =K44+K49-K50 -> 1839.2476 | L52: =L44+L49-L50 -> 1844.9791 | ... N52: =N44+N49-N50 -> 1857.8157
B53: Admin & Selling Expenses | C53: INR Lacs | E53: =E28*Assumptions!E104 -> 4.8267576 | F53: =F28*Assumptions!F104 -> 29.541494 | G53: =G28*Assumptions!G104 -> 37.796296 | H53: =H28*Assumptions!H104 -> 46.310972 | I53: =I28*Assumptions!I104 -> 54.825649 | J53: =J28*Assumptions!J104 -> 63.340326 | K53: =K28*Assumptions!K104 -> 63.860076 | L53: =L28*Assumptions!L104 -> 63.860076 | ... N53: =N28*Assumptions!N104 -> 63.860076
B55: EBITDA | C55: INR Lacs | E55: =E28-E52-E53 -> 7.4629124 | F55: =F28-F52-F53 -> 82.094516 | G55: =G28-G52-G53 -> 117.18738 | H55: =H28-H52-H53 -> 154.04325 | I55: =I28-I52-I53 -> 190.57715 | J55: =J28-J52-J53 -> 226.76215 | K55: =K28-K52-K53 -> 225.56151 | L55: =L28-L52-L53 -> 219.83007 | ... N55: =N28-N52-N53 -> 206.9934
E56: =E55/E28 -> 0.046384631 | F56: =F55/F28 -> 0.083368685 | G56: =G55/G28 -> 0.093014975 | H56: =H55/H28 -> 0.099788392 | I56: =I55/I28 -> 0.10428175 | J56: =J55/J28 -> 0.10740179 | K56: =K55/K28 -> 0.10596363 | L56: =L55/L28 -> 0.10327113 | ... N56: =N55/N28 -> 0.097240753

Sheet Depreciation
B2: Depreciation
B4: Depreciation Rates | E4: Amount
C5: SLM (Comp Act) | D5: WDV (IT Act)
B6: Land | C6: =Assumptions!D131 -> 0 | D6: =Assumptions!E131 -> 0 | E6: ='Project Cost'!L5 -> 9.8563851
B7: Factory Building | C7: =Assumptions!D132 -> 0.0317 | D7: =Assumptions!E132 -> 0.1 | E7: ='Project Cost'!L6 -> 0
B8: Non-Factory Building | C8: =Assumptions!D133 -> 0.0317 | D8: =Assumptions!E133 -> 0.1 | E8: ='Project Cost'!L7 -> 0
B9: Plant & Machinery | C9: =Assumptions!D134 -> 0.0633 | D9: =Assumptions!E134 -> 0.15 | E9: ='Project Cost'!L8 -> 124.50171
B10: Utilities & Electrical Equipments | C10: =Assumptions!D135 -> 0.095 | D10: =Assumptions!E135 -> 0.15 | E10: ='Project Cost'!L9 -> 14.525199
B11: Miscellaneous Fixed Assets | C11: =Assumptions!D136 -> 0.095 | D11: =Assumptions!E136 -> 0.15 | E11: ='Project Cost'!L10 -> 0
B12: Vehicle | C12: =Assumptions!D137 -> 0.19 | D12: =Assumptions!E137 -> 0.15 | E12: ='Project Cost'!L11 -> 0
B13: Computer | C13: =Assumptions!D138 -> 0.1583 | D13: =Assumptions!E138 -> 0.6 | E13: ='Project Cost'!L12 -> 1.0375142
B14: Furniture | C14: =Assumptions!D139 -> 0.095 | D14: =Assumptions!E139 -> 0.1 | E14: ='Project Cost'!L13 -> 2.0750284
B15: % of value that can be depreciated | C15: =Assumptions!D140 -> 0.95 | D15: =Assumptions!E140 -> -
E16: =SUM(E6:E15) -> 151.99583
B18: Accounting Depreciation | C18: (SLM)
B19: FY Ending | E19: =Assumptions!E82 -> 44286 | F19: =Assumptions!F82 -> 44651 | G19: =Assumptions!G82 -> 45016 | H19: =Assumptions!H82 -> 45382 | I19: =Assumptions!I82 -> 45747 | J19: =Assumptions!J82 -> 46112 | K19: =Assumptions!K82 -> 46477 | L19: =Assumptions!L82 -> 46843 | ... N19: =Assumptions!N82 -> 47573
B20: No. of Months | E20: =Assumptions!E83 -> 3 | F20: =Assumptions!F83 -> 12 | G20: =Assumptions!G83 -> 12 | H20: =Assumptions!H83 -> 12 | I20: =Assumptions!I83 -> 12 | J20: =Assumptions!J83 -> 12 | K20: =Assumptions!K83 -> 12 | L20: =Assumptions!L83 -> 12 | ... N20: =Assumptions!N83 -> 12
B22: Land | C22: =C6 -> 0
B23: Opening Block | E23: 0 | F23: =E25 -> 9.8563851 | G23: =F25 -> 9.8563851 | H23: =G25 -> 9.8563851 | I23: =H25 -> 9.8563851 | J23: =I25 -> 9.8563851 | K23: =J25 -> 9.8563851 | L23: =K25 -> 9.8563851 | M23: =L25 -> 9.8563851 | N23: =M25 -> 9.8563851
B24: Additions during the year | E24: =E6 -> 9.8563851
B25: Gross Block | E25: =E23+E24 -> 9.8563851 | F25: =F23+F24 -> 9.8563851 | G25: =G23+G24 -> 9.8563851 | H25: =H23+H24 -> 9.8563851 | I25: =I23+I24 -> 9.8563851 | J25: =J23+J24 -> 9.8563851 | K25: =K23+K24 -> 9.8563851 | L25: =L23+L24 -> 9.8563851 | ... N25: =N23+N24 -> 9.8563851
B26: Block Available for Depreciation | E26: =E25/12*E20 -> 2.4640963 | F26: =F25/12*F20 -> 9.8563851 | G26: =G25/12*G20 -> 9.8563851 | H26: =H25/12*H20 -> 9.8563851 | I26: =I25/12*I20 -> 9.8563851 | J26: =J25/12*J20 -> 9.8563851 | K26: =K25/12*K20 -> 9.8563851 | L26: =L25/12*L20 -> 9.8563851 | ... N26: =N25/12*N20 -> 9.8563851
B27: Depreciation | E27: =E26*$C$6 -> 0 | F27: =F26*$C$6 -> 0 | G27: =G26*$C$6 -> 0 | H27: =H26*$C$6 -> 0 | I27: =I26*$C$6 -> 0 | J27: =J26*$C$6 -> 0 | K27: =K26*$C$6 -> 0 | L27: =L26*$C$6 -> 0 | ... N27: =N26*$C$6 -> 0
B28: Accumulated Depreciation | E28: =D28+E27 -> 0 | F28: =E28+F27 -> 0 | G28: =F28+G27 -> 0 | H28: =G28+H27 -> 0 | I28: =H28+I27 -> 0 | J28: =I28+J27 -> 0 | K28: =J28+K27 -> 0 | L28: =K28+L27 -> 0 | ... N28: =M28+N27 -> 0
B29: Net Block | E29: =E25-E28 -> 9.8563851 | F29: =F25-F28 -> 9.8563851 | G29: =G25-G28 -> 9.8563851 | H29: =H25-H28 -> 9.8563851 | I29: =I25-I28 -> 9.8563851 | J29: =J25-J28 -> 9.8563851 | K29: =K25-K28 -> 9.8563851 | L29: =L25-L28 -> 9.8563851 | ... N29: =N25-N28 -> 9.8563851
B31: Factory Building | C31: =C7 -> 0.0317
B32: Opening Block
B33: Additions during the year
B34: Gross Block
B35: Block Available for Depreciation
B36: Depreciation
B37: Accumulated Depreciation
B38: Net Block
B40: Non-Factory Building | C40: =C8 -> 0.0317
B41: Opening Block
B42: Additions during the year
B43: Gross Block
B44: Block Available for Depreciation
B45: Depreciation
B46: Accumulated Depreciation
...

Sheet WC
B2: Working Capital
B4: FY Ending | C4: Norm | E4: =Assumptions!E82 -> 44286 | F4: =Assumptions!F82 -> 44651 | G4: =Assumptions!G82 -> 45016 | H4: =Assumptions!H82 -> 45382 | I4: =Assumptions!I82 -> 45747 | J4: =Assumptions!J82 -> 46112 | K4: =Assumptions!K82 -> 46477 | L4: =Assumptions!L82 -> 46843 | ... N4: =Assumptions!N82 -> 47573
B5: No of months | E5: =Assumptions!E83 -> 3 | F5: =Assumptions!F83 -> 12 | G5: =Assumptions!G83 -> 12 | H5: =Assumptions!H83 -> 12 | I5: =Assumptions!I83 -> 12 | J5: =Assumptions!J83 -> 12 | K5: =Assumptions!K83 -> 12 | L5: =Assumptions!L83 -> 12 | ... N5: =Assumptions!N83 -> 12
B6: Current Assets
B7: Raw Material Inventory | C7: =Assumptions!D117 -> 0.75 | E7: =PL!D14/WC!E5*WC!$C$7 -> 27.594 | F7: =PL!E14/WC!F5*WC!$C$7 -> 32.193 | G7: =PL!F14/WC!G5*WC!$C$7 -> 41.391 | H7: =PL!G14/WC!H5*WC!$C$7 -> 50.589 | I7: =PL!H14/WC!I5*WC!$C$7 -> 59.787 | J7: =PL!I14/WC!J5*WC!$C$7 -> 68.985 | K7: =PL!J14/WC!K5*WC!$C$7 -> 68.985 | L7: =PL!K14/WC!L5*WC!$C$7 -> 68.985 | ... N7: =PL!M14/WC!N5*WC!$C$7 -> 68.985
B8: WIP Inventory | C8: =Assumptions!D118 -> 0.5 | E8: =CoP!E42 -> 25.294 | F8: =CoP!F42 -> 29.3208 | G8: =CoP!G42 -> 37.25979 | H8: =CoP!H42 -> 45.20873 | I8: =CoP!I42 -> 53.168446 | J8: =CoP!J42 -> 61.139841 | K8: =CoP!K42 -> 61.317899 | L8: =CoP!L42 -> 61.50969 | ... N8: =CoP!N42 -> 61.939263
B9: FG Inventory | C9: =Assumptions!D119 -> 0.25 | E9: =CoP!E50 -> 15.80875 | F9: =CoP!F50 -> 18.3255 | G9: =CoP!G50 -> 23.287369 | H9: =CoP!H50 -> 28.255456 | I9: =CoP!I50 -> 33.230279 | J9: =CoP!J50 -> 38.212401 | K9: =CoP!K50 -> 38.323687 | L9: =CoP!L50 -> 38.443556 | ... N9: =CoP!N50 -> 38.71204
B10: Sundry Debtors | C10: =Assumptions!D120 -> 1.5 | E10: =PL!D10/WC!E5*$C$10 -> 80.44596 | F10: =PL!E10/WC!F5*$C$10 -> 123.08956 | G10: =PL!F10/WC!G5*$C$10 -> 157.48457 | H10: =PL!G10/WC!H5*$C$10 -> 192.96239 | I10: =PL!H10/WC!I5*$C$10 -> 228.4402 | J10: =PL!I10/WC!J5*$C$10 -> 263.91803 | K10: =PL!J10/WC!K5*$C$10 -> 266.08365 | L10: =PL!K10/WC!L5*$C$10 -> 266.08365 | ... N10: =PL!M10/WC!N5*$C$10 -> 266.08365
B11: Stores & Spares | C11: =Assumptions!D121 -> 0.01 | E11: =PL!D10*WC!$C$11 -> 1.6089192 | F11: =PL!E10*WC!$C$11 -> 9.8471646 | G11: =PL!F10*WC!$C$11 -> 12.598765 | H11: =PL!G10*WC!$C$11 -> 15.436991 | I11: =PL!H10*WC!$C$11 -> 18.275216 | J11: =PL!I10*WC!$C$11 -> 21.113442 | K11: =PL!J10*WC!$C$11 -> 21.286692 | L11: =PL!K10*WC!$C$11 -> 21.286692 | ... N11: =PL!M10*WC!$C$11 -> 21.286692
B12: Total Current Assets | E12: =SUM(E7:E11) -> 150.75163 | F12: =SUM(F7:F11) -> 212.77602 | G12: =SUM(G7:G11) -> 272.02149 | H12: =SUM(H7:H11) -> 332.45256 | I12: =SUM(I7:I11) -> 392.90115 | J12: =SUM(J7:J11) -> 453.36871 | K12: =SUM(K7:K11) -> 455.99693 | L12: =SUM(L7:L11) -> 456.30859 | ... N12: =SUM(N7:N11) -> 457.00665
B13: Current Liabilities
B14: Creditors on Consumables | C14: =Assumptions!D122 -> 1 | E14: =E27/E5*$C$14 -> 45.99 | F14: =F27/F5*$C$14 -> 43.30725 | G14: =G27/G5*$C$14 -> 55.9545 | H14: =H27/H5*$C$14 -> 68.2185 | I14: =I27/I5*$C$14 -> 80.4825 | J14: =J27/J5*$C$14 -> 92.7465 | K14: =K27/K5*$C$14 -> 91.98 | L14: =L27/L5*$C$14 -> 91.98 | ... N14: =N27/N5*$C$14 -> 91.98
B15: Other Current Liabilities (advance from customers)
B16: Total Current Liabilities | E16: =E14+E15 -> 45.99 | F16: =F14+F15 -> 43.30725 | G16: =G14+G15 -> 55.9545 | H16: =H14+H15 -> 68.2185 | I16: =I14+I15 -> 80.4825 | J16: =J14+J15 -> 92.7465 | K16: =K14+K15 -> 91.98 | L16: =L14+L15 -> 91.98 | ... N16: =N14+N15 -> 91.98
B17: Net Working Capital Gap | E17: =E12-E16 -> 104.76163 | F17: =F12-F16 -> 169.46877 | G17: =G12-G16 -> 216.06699 | H17: =H12-H16 -> 264.23406 | I17: =I12-I16 -> 312.41865 | J17: =J12-J16 -> 360.62221 | K17: =K12-K16 -> 364.01693 | L17: =L12-L16 -> 364.32859 | ... N17: =N12-N16 -> 365.02665
B18: Margin Money for WC | C18: =Assumptions!D126 -> 0.25 | E18: =E17*$C$18 -> 26.190407 | F18: =F17*$C$18 -> 42.367193 | G18: =G17*$C$18 -> 54.016747 | H18: =H17*$C$18 -> 66.058515 | I18: =I17*$C$18 -> 78.104662 | J18: =J17*$C$18 -> 90.155552 | K18: =K17*$C$18 -> 91.004232 | L18: =L17*$C$18 -> 91.082147 | ... N18: =N17*$C$18 -> 91.256661
B19: Bank Finance Available | E19: =E17-E18 -> 78.571222 | F19: =F17-F18 -> 127.10158 | G19: =G17-G18 -> 162.05024 | H19: =H17-H18 -> 198.17555 | I19: =I17-I18 -> 234.31398 | J19: =J17-J18 -> 270.46666 | K19: =K17-K18 -> 273.0127 | L19: =L17-L18 -> 273.24644 | ... N19: =N17-N18 -> 273.76998
B20: Bank Borrowings | E20: =E19 -> 78.571222 | F20: =F19 -> 127.10158 | G20: =G19 -> 162.05024 | H20: =H19 -> 198.17555 | I20: =I19 -> 234.31398 | J20: =J19 -> 270.46666 | K20: =K19 -> 273.0127 | L20: =L19 -> 273.24644 | ... N20: =N19 -> 273.76998
B22: WC Interest | C22: =Assumptions!D125 -> 0.1 | E22: =E20*$C$22/12*E5 -> 1.9642805 | F22: =F20*$C$22/12*F5 -> 12.710158 | G22: =G20*$C$22/12*G5 -> 16.205024 | H22: =H20*$C$22/12*H5 -> 19.817555 | I22: =I20*$C$22/12*I5 -> 23.431398 | J22: =J20*$C$22/12*J5 -> 27.046666 | K22: =K20*$C$22/12*K5 -> 27.30127 | L22: =L20*$C$22/12*L5 -> 27.324644 | ... N22: =N20*$C$22/12*N5 -> 27.376998
B23: Bank Charges | C23: =Assumptions!D124 -> 0.02 | E23: =E20*$C$23 -> 1.5714244 | F23: =F20*$C$23 -> 2.5420316 | G23: =G20*$C$23 -> 3.2410048 | H23: =H20*$C$23 -> 3.9635109 | I23: =I20*$C$23 -> 4.6862797 | J23: =J20*$C$23 -> 5.4093331 | K23: =K20*$C$23 -> 5.4602539 | L23: =L20*$C$23 -> 5.4649288 | ... N23: =N20*$C$23 -> 5.4753997
B25: Raw Material Purchase | E25: =E4 -> 44286 | F25: =F4 -> 44651 | G25: =G4 -> 45016 | H25: =H4 -> 45382 | I25: =I4 -> 45747 | J25: =J4 -> 46112 | K25: =K4 -> 46477 | L25: =L4 -> 46843 | ... N25: =N4 -> 47573
B26: Opening Stock | E26: 0 | F26: =E28 -> 27.594 | G26: =F28 -> 32.193 | H26: =G28 -> 41.391 | I26: =H28 -> 50.589 | J26: =I28 -> 59.787 | K26: =J28 -> 68.985 | L26: =K28 -> 68.985 | M26: =L28 -> 68.985 | N26: =M28 -> 68.985
B27: Purchase | E27: =E29+E28-E26 -> 137.97 | F27: =F29+F28-F26 -> 519.687 | G27: =G29+G28-G26 -> 671.454 | H27: =H29+H28-H26 -> 818.622 | I27: =I29+I28-I26 -> 965.79 | J27: =J29+J28-J26 -> 1112.958 | K27: =K29+K28-K26 -> 1103.76 | L27: =L29+L28-L26 -> 1103.76 | ... N27: =N29+N28-N26 -> 1103.76
B28: Closing Stock | E28: =E7 -> 27.594 | F28: =F7 -> 32.193 | G28: =G7 -> 41.391 | H28: =H7 -> 50.589 | I28: =I7 -> 59.787 | J28: =J7 -> 68.985 | K28: =K7 -> 68.985 | L28: =L7 -> 68.985 | ... N28: =N7 -> 68.985
B29: Consumption | E29: =PL!D14 -> 110.376 | F29: =PL!E14 -> 515.088 | G29: =PL!F14 -> 662.256 | H29: =PL!G14 -> 809.424 | I29: =PL!H14 -> 956.592 | J29: =PL!I14 -> 1103.76 | K29: =PL!J14 -> 1103.76 | L29: =PL!K14 -> 1103.76 | ... N29: =PL!M14 -> 1103.76
B32: Turnover Method of Working Capital Assessment
B33: NWC
B34: 8% of Gross Sales
B35: Max of Both
B37: 33% of Gross Sales
B38: Bank Borrowing
B40: MPBF as per CMA

Sheet PL
B2: Profit & Loss
M3: INR Lacs
B4: FY Ending | C4: =EOMONTH(D4,-12) -> 43921 | D4: =Assumptions!E82 -> 44286 | E4: =Assumptions!F82 -> 44651 | F4: =Assumptions!G82 -> 45016 | G4: =Assumptions!H82 -> 45382 | H4: =Assumptions!I82 -> 45747 | I4: =Assumptions!J82 -> 46112 | J4: =Assumptions!K82 -> 46477 | K4: =Assumptions!L82 -> 46843 | ... M4: =Assumptions!N82 -> 47573
B5: No of months | D5: =Assumptions!E83 -> 3 | E5: =Assumptions!F83 -> 12 | F5: =Assumptions!G83 -> 12 | G5: =Assumptions!H83 -> 12 | H5: =Assumptions!I83 -> 12 | I5: =Assumptions!J83 -> 12 | J5: =Assumptions!K83 -> 12 | K5: =Assumptions!L83 -> 12 | ... M5: =Assumptions!N83 -> 12
B6: Sales of Electroforged Gratings | D6: =CoP!E25 -> 155.925 | E6: =CoP!F25 -> 961.5375 | F6: =CoP!G25 -> 1230.075 | G6: =CoP!H25 -> 1507.275 | H6: =CoP!I25 -> 1784.475 | I6: =CoP!J25 -> 2061.675 | J6: =CoP!K25 -> 2079 | K6: =CoP!L25 -> 2079 | ... M6: =CoP!N25 -> 2079
B7: Scrap Sales | D7: =CoP!E26 -> 4.96692 | E7: =CoP!F26 -> 23.17896 | F7: =CoP!G26 -> 29.80152 | G7: =CoP!H26 -> 36.42408 | H7: =CoP!I26 -> 43.04664 | I7: =CoP!J26 -> 49.6692 | J7: =CoP!K26 -> 49.6692 | K7: =CoP!L26 -> 49.6692 | ... M7: =CoP!N26 -> 49.6692
B8: Clamp and Hardware Sales | D8: =CoP!E27 -> 0 | E8: =CoP!F27 -> 0 | F8: =CoP!G27 -> 0 | G8: =CoP!H27 -> 0 | H8: =CoP!I27 -> 0 | I8: =CoP!J27 -> 0 | J8: =CoP!K27 -> 0 | K8: =CoP!L27 -> 0 | ... M8: =CoP!N27 -> 0
B9: Other Operating Income
B10: Net Sales | D10: =SUM(D6:D9) -> 160.89192 | E10: =SUM(E6:E9) -> 984.71646 | F10: =SUM(F6:F9) -> 1259.8765 | G10: =SUM(G6:G9) -> 1543.6991 | H10: =SUM(H6:H9) -> 1827.5216 | I10: =SUM(I6:I9) -> 2111.3442 | J10: =SUM(J6:J9) -> 2128.6692 | K10: =SUM(K6:K9) -> 2128.6692 | ... M10: =SUM(M6:M9) -> 2128.6692
B11: GST | C11: 0.18
B12: Gross Sales
B13: Expenses
B14: Raw Material Cost | D14: =CoP!E30 -> 110.376 | E14: =CoP!F30 -> 515.088 | F14: =CoP!G30 -> 662.256 | G14: =CoP!H30 -> 809.424 | H14: =CoP!I30 -> 956.592 | I14: =CoP!J30 -> 1103.76 | J14: =CoP!K30 -> 1103.76 | K14: =CoP!L30 -> 1103.76 | ... M14: =CoP!N30 -> 1103.76
B15: Galv. Charges | D15: =CoP!E31 -> 45.738 | E15: =CoP!F31 -> 213.444 | F15: =CoP!G31 -> 274.428 | G15: =CoP!H31 -> 335.412 | H15: =CoP!I31 -> 396.396 | I15: =CoP!J31 -> 457.38 | J15: =CoP!K31 -> 457.38 | K15: =CoP!L31 -> 457.38 | ... M15: =CoP!N31 -> 457.38
B16: Power Cost | D16: =CoP!E32 -> 5.184 | E16: =CoP!F32 -> 24.192 | F16: =CoP!G32 -> 31.104 | G16: =CoP!H32 -> 38.016 | H16: =CoP!I32 -> 44.928 | I16: =CoP!J32 -> 51.84 | J16: =CoP!K32 -> 51.84 | K16: =CoP!L32 -> 51.84 | ... M16: =CoP!N32 -> 51.84
B17: Fabrication Cost | D17: =CoP!E33 -> 8.1 | E17: =CoP!F33 -> 37.8 | F17: =CoP!G33 -> 48.6 | G17: =CoP!H33 -> 59.4 | H17: =CoP!I33 -> 70.2 | I17: =CoP!J33 -> 81 | J17: =CoP!K33 -> 81 | K17: =CoP!L33 -> 81 | ... M17: =CoP!N33 -> 81
B18: Consumable | D18: =CoP!E34 -> 4.158 | E18: =CoP!F34 -> 19.404 | F18: =CoP!G34 -> 24.948 | G18: =CoP!H34 -> 30.492 | H18: =CoP!I34 -> 36.036 | I18: =CoP!J34 -> 41.58 | J18: =CoP!K34 -> 41.58 | K18: =CoP!L34 -> 41.58 | ... M18: =CoP!N34 -> 41.58
B19: Testing & Maint | D19: =CoP!E35 -> 2.079 | E19: =CoP!F35 -> 9.702 | F19: =CoP!G35 -> 12.474 | G19: =CoP!H35 -> 15.246 | H19: =CoP!I35 -> 18.018 | I19: =CoP!J35 -> 20.79 | J19: =CoP!K35 -> 20.79 | K19: =CoP!L35 -> 20.79 | ... M19: =CoP!N35 -> 20.79
B20: Salaries & Wages | D20: =CoP!E36 -> 9.57 | E20: =CoP!F36 -> 40.194 | F20: =CoP!G36 -> 42.2037 | G20: =CoP!H36 -> 44.313885 | H20: =CoP!I36 -> 46.529579 | I20: =CoP!J36 -> 48.856058 | J20: =CoP!K36 -> 51.298861 | K20: =CoP!L36 -> 53.863804 | ... M20: =CoP!N36 -> 59.384844
B21: Factory Rent | D21: =CoP!E37 -> 4.5 | E21: =CoP!F37 -> 19.8 | F21: =CoP!G37 -> 21.78 | G21: =CoP!H37 -> 23.958 | H21: =CoP!I37 -> 26.3538 | I21: =CoP!J37 -> 28.98918 | J21: =CoP!K37 -> 31.888098 | K21: =CoP!L37 -> 35.076908 | ... M21: =CoP!N37 -> 42.443058
B22: Other Operating Expenses
B23: Total Manufacturing Expenses | D23: =SUM(D14:D22) -> 189.705 | E23: =SUM(E14:E22) -> 879.624 | F23: =SUM(F14:F22) -> 1117.7937 | G23: =SUM(G14:G22) -> 1356.2619 | H23: =SUM(H14:H22) -> 1595.0534 | I23: =SUM(I14:I22) -> 1834.1952 | J23: =SUM(J14:J22) -> 1839.537 | K23: =SUM(K14:K22) -> 1845.2907 | ... M23: =SUM(M14:M22) -> 1858.1779
B24: WIP Opening | D24: =CoP!E41 -> 0 | E24: =CoP!F41 -> 25.294 | F24: =CoP!G41 -> 29.3208 | G24: =CoP!H41 -> 37.25979 | H24: =CoP!I41 -> 45.20873 | I24: =CoP!J41 -> 53.168446 | J24: =CoP!K41 -> 61.139841 | K24: =CoP!L41 -> 61.317899 | ... M24: =CoP!N41 -> 61.716386
B25: WIP Closing | D25: =CoP!E42 -> 25.294 | E25: =CoP!F42 -> 29.3208 | F25: =CoP!G42 -> 37.25979 | G25: =CoP!H42 -> 45.20873 | H25: =CoP!I42 -> 53.168446 | I25: =CoP!J42 -> 61.139841 | J25: =CoP!K42 -> 61.317899 | K25: =CoP!L42 -> 61.50969 | ... M25: =CoP!N42 -> 61.939263
B26: Cost of Production | D26: =D23+D24-D25 -> 164.411 | E26: =E23+E24-E25 -> 875.5972 | F26: =F23+F24-F25 -> 1109.8547 | G26: =G23+G24-G25 -> 1348.3129 | H26: =H23+H24-H25 -> 1587.0937 | I26: =I23+I24-I25 -> 1826.2238 | J26: =J23+J24-J25 -> 1839.3589 | K26: =K23+K24-K25 -> 1845.0989 | ... M26: =M23+M24-M25 -> 1857.955
B27: Admin & Selling Expenses | D27: =CoP!E53 -> 4.8267576 | E27: =CoP!F53 -> 29.541494 | F27: =CoP!G53 -> 37.796296 | G27: =CoP!H53 -> 46.310972 | H27: =CoP!I53 -> 54.825649 | I27: =CoP!J53 -> 63.340326 | J27: =CoP!K53 -> 63.860076 | K27: =CoP!L53 -> 63.860076 | ... M27: =CoP!N53 -> 63.860076
B28: FG Opening | D28: =CoP!E49 -> 0 | E28: =CoP!F49 -> 15.80875 | F28: =CoP!G49 -> 18.3255 | G28: =CoP!H49 -> 23.287369 | H28: =CoP!I49 -> 28.255456 | I28: =CoP!J49 -> 33.230279 | J28: =CoP!K49 -> 38.212401 | K28: =CoP!L49 -> 38.323687 | ... M28: =CoP!N49 -> 38.572742
B29: FG Closing | D29: =CoP!E50 -> 15.80875 | E29: =CoP!F50 -> 18.3255 | F29: =CoP!G50 -> 23.287369 | G29: =CoP!H50 -> 28.255456 | H29: =CoP!I50 -> 33.230279 | I29: =CoP!J50 -> 38.212401 | J29: =CoP!K50 -> 38.323687 | K29: =CoP!L50 -> 38.443556 | ... M29: =CoP!N50 -> 38.71204
B30: Cost of Goods Sold | D30: =D26+D27+D28-D29 -> 153.42901 | E30: =E26+E27+E28-E29 -> 902.62194 | F30: =F26+F27+F28-F29 -> 1142.6891 | G30: =G26+G27+G28-G29 -> 1389.6558 | H30: =H26+H27+H28-H29 -> 1636.9445 | I30: =I26+I27+I28-I29 -> 1884.582 | J30: =J26+J27+J28-J29 -> 1903.1077 | K30: =K26+K27+K28-K29 -> 1908.8391 | ... M30: =M26+M27+M28-M29 -> 1921.6758
B31: EBITDA | D31: =D10-D30 -> 7.4629124 | E31: =E10-E30 -> 82.094516 | F31: =F10-F30 -> 117.18738 | G31: =G10-G30 -> 154.04325 | H31: =H10-H30 -> 190.57715 | I31: =I10-I30 -> 226.76215 | J31: =J10-J30 -> 225.56151 | K31: =K10-K30 -> 219.83007 | ... M31: =M10-M30 -> 206.9934
B32: EBITDA Margin | D32: =D31/D10 -> 0.046384631 | E32: =E31/E10 -> 0.083368685 | F32: =F31/F10 -> 0.093014975 | G32: =G31/G10 -> 0.099788392 | H32: =H31/H10 -> 0.10428175 | I32: =I31/I10 -> 0.10740179 | J32: =J31/J10 -> 0.10596363 | K32: =K31/K10 -> 0.10327113 | ... M32: =M31/M10 -> 0.097240753
B33: Depreciation | D33: =Depreciation!E193 -> 2.4055545 | E33: =Depreciation!F193 -> 9.6222181 | F33: =Depreciation!G193 -> 9.6222181 | G33: =Depreciation!H193 -> 9.6222181 | H33: =Depreciation!I193 -> 9.6222181 | I33: =Depreciation!J193 -> 9.6222181 | J33: =Depreciation!K193 -> 9.6222181 | K33: =Depreciation!L193 -> 9.4690032 | ... M33: =Depreciation!N193 -> 9.4579796
B34: EBIT | D34: =D31-D33 -> 5.0573579 | E34: =E31-E33 -> 72.472298 | F34: =F31-F33 -> 107.56517 | G34: =G31-G33 -> 144.42103 | H34: =H31-H33 -> 180.95493 | I34: =I31-I33 -> 217.13994 | J34: =J31-J33 -> 215.93929 | K34: =K31-K33 -> 210.36107 | ... M34: =M31-M33 -> 197.53542
B35: Interest Cost
B36: TL Interest | D36: ='Capex, Debt'!E115 -> 2.875 | E36: ='Capex, Debt'!F115 -> 11.095703 | F36: ='Capex, Debt'!G115 -> 9.703125 | G36: ='Capex, Debt'!H115 -> 8.265625 | H36: ='Capex, Debt'!I115 -> 6.828125 | I36: ='Capex, Debt'!J115 -> 5.390625 | J36: ='Capex, Debt'!K115 -> 3.953125 | K36: ='Capex, Debt'!L115 -> 2.515625 | ... M36: ='Capex, Debt'!N115 -> 0.044921875
B37: WC Interest | D37: =WC!E22 -> 1.9642805 | E37: =WC!F22 -> 12.710158 | F37: =WC!G22 -> 16.205024 | G37: =WC!H22 -> 19.817555 | H37: =WC!I22 -> 23.431398 | I37: =WC!J22 -> 27.046666 | J37: =WC!K22 -> 27.30127 | K37: =WC!L22 -> 27.324644 | ... M37: =WC!N22 -> 27.376998
B38: Bank Charges | D38: =WC!E23 -> 1.5714244 | E38: =WC!F23 -> 2.5420316 | F38: =WC!G23 -> 3.2410048 | G38: =WC!H23 -> 3.9635109 | H38: =WC!I23 -> 4.6862797 | I38: =WC!J23 -> 5.4093331 | J38: =WC!K23 -> 5.4602539 | K38: =WC!L23 -> 5.4649288 | ... M38: =WC!N23 -> 5.4753997
B39: PBT | D39: =D34-SUM(D36:D38) -> -1.3533471 | E39: =E34-SUM(E36:E38) -> 46.124405 | F39: =F34-SUM(F36:F38) -> 78.416011 | G39: =G34-SUM(G36:G38) -> 112.37434 | H39: =H34-SUM(H36:H38) -> 146.00913 | I39: =I34-SUM(I36:I38) -> 179.29331 | J39: =J34-SUM(J36:J38) -> 179.22464 | K39: =K34-SUM(K36:K38) -> 175.05587 | ... M39: =M34-SUM(M36:M38) -> 164.6381
B40: Provision for Tax
B41: Current Tax | D41: =D63 -> 0 | E41: =E63 -> 6.5522222 | F41: =F63 -> 17.942274 | G41: =G63 -> 27.138693 | H41: =H63 -> 36.144593 | I41: =I63 -> 44.976612 | J41: =J63 -> 45.344412 | K41: =K63 -> 44.583381 | ... M41: =M63 -> 42.472157
...

Sheet CF
B2: Cash Flows
M3: INR Lacs
B4: FY Ending | D4: =PL!D4 -> 44286 | E4: =PL!E4 -> 44651 | F4: =PL!F4 -> 45016 | G4: =PL!G4 -> 45382 | H4: =PL!H4 -> 45747 | I4: =PL!I4 -> 46112 | J4: =PL!J4 -> 46477 | K4: =PL!K4 -> 46843 | ... M4: =PL!M4 -> 47573
B5: PAT | D5: =PL!D43 -> -1.3533471 | E5: =PL!E43 -> 34.515815 | F5: =PL!F43 -> 58.680269 | G5: =PL!G43 -> 84.091967 | H5: =PL!H43 -> 109.26155 | I5: =PL!I43 -> 134.16877 | J5: =PL!J43 -> 134.11738 | K5: =PL!K43 -> 130.99781 | ... M5: =PL!M43 -> 123.20198
B6: Depreciation | D6: =PL!D33 -> 2.4055545 | E6: =PL!E33 -> 9.6222181 | F6: =PL!F33 -> 9.6222181 | G6: =PL!G33 -> 9.6222181 | H6: =PL!H33 -> 9.6222181 | I6: =PL!I33 -> 9.6222181 | J6: =PL!J33 -> 9.6222181 | K6: =PL!K33 -> 9.4690032 | ... M6: =PL!M33 -> 9.4579796
B7: Deferred Tax Liability/(Asset) | D7: =PL!D42 -> 0 | E7: =PL!E42 -> 5.0563682 | F7: =PL!F42 -> 1.7934679 | G7: =PL!G42 -> 1.1436815 | H7: =PL!H42 -> 0.60298432 | I7: =PL!I42 -> 0.14792856 | J7: =PL!J42 -> -0.23715456 | K7: =PL!K42 -> -0.52531878 | ... M7: =PL!M42 -> -1.0360406
B8: Increase in Current Liability | D8: =WC!E16-WC!D16 -> 45.99 | E8: =WC!F16-WC!E16 -> -2.68275 | F8: =WC!G16-WC!F16 -> 12.64725 | G8: =WC!H16-WC!G16 -> 12.264 | H8: =WC!I16-WC!H16 -> 12.264 | I8: =WC!J16-WC!I16 -> 12.264 | J8: =WC!K16-WC!J16 -> -0.7665 | K8: =WC!L16-WC!K16 -> 0 | ... M8: =WC!N16-WC!M16 -> 0
B9: Increase in Equity - Share Capital | D9: ='Capex, Debt'!E102 -> 63.186241
