Workbook
Name UPDATE: 'Data Sheet'!$E$1

Sheet Profit & Loss
A1: ='Data Sheet'!B1 -> ITC LTD | H1: =UPDATE | M1: SCREENER.IN
A3: Narration | B3: ='Data Sheet'!B16 -> 42460 | C3: ='Data Sheet'!C16 -> 42825 | D3: ='Data Sheet'!D16 -> 43190 | E3: ='Data Sheet'!E16 -> 43555 | F3: ='Data Sheet'!F16 -> 43921 | G3: ='Data Sheet'!G16 -> 44286 | H3: ='Data Sheet'!H16 -> 44651 | I3: ='Data Sheet'!I16 -> 45016 | ... K3: ='Data Sheet'!K16 -> 45747 | L3: Trailing | M3: Best Case | N3: Worst Case
A4: Sales | B4: ='Data Sheet'!B17 -> 39192.1 | C4: ='Data Sheet'!C17 -> 42767.6 | D4: ='Data Sheet'!D17 -> 43448.94 | E4: ='Data Sheet'!E17 -> 48339.58 | F4: ='Data Sheet'!F17 -> 49387.7 | G4: ='Data Sheet'!G17 -> 49257.45 | H4: ='Data Sheet'!H17 -> 60644.54 | I4: ='Data Sheet'!I17 -> 70919.03 | ... K4: ='Data Sheet'!K17 -> 75323.34 | L4: =SUM(Quarters!H4:K4) -> 79808.72 | M4: =$K4+M23*K4 -> 83518.968 | N4: =$K4+N23*L4 -> 81303.23
A5: Expenses | B5: =SUM('Data Sheet'!B18,'Data Sheet'!B20:B24, -1*'Data Sheet'!B19) -> 24660.61 | C5: =SUM('Data Sheet'!C18,'Data Sheet'!C20:C24, -1*'Data Sheet'!C19) -> 27298.09 | D5: =SUM('Data Sheet'!D18,'Data Sheet'!D20:D24, -1*'Data Sheet'!D19) -> 26928.35 | E5: =SUM('Data Sheet'!E18,'Data Sheet'!E20:E24, -1*'Data Sheet'!E19) -> 29802.19 | F5: =SUM('Data Sheet'!F18,'Data Sheet'!F20:F24, -1*'Data Sheet'!F19) -> 30044.16 | G5: =SUM('Data Sheet'!G18,'Data Sheet'!G20:G24, -1*'Data Sheet'!G19) -> 32192.67 | H5: =SUM('Data Sheet'!H18,'Data Sheet'!H20:H24, -1*'Data Sheet'!H19) -> 40021.39 | I5: =SUM('Data Sheet'!I18,'Data Sheet'!I20:I24, -1*'Data Sheet'!I19) -> 45214.77 | ... K5: =SUM('Data Sheet'!K18,'Data Sheet'!K20:K24, -1*'Data Sheet'!K19) -> 49483.89 | L5: =SUM(Quarters!H5:K5) -> 52895.65 | M5: =M4-M6 -> 53597.014 | N5: =N4-N6 -> 53886.182
A6: Operating Profit | B6: =B4-B5 -> 14531.49 | C6: =C4-C5 -> 15469.51 | D6: =D4-D5 -> 16520.59 | E6: =E4-E5 -> 18537.39 | F6: =F4-F5 -> 19343.54 | G6: =G4-G5 -> 17064.78 | H6: =H4-H5 -> 20623.15 | I6: =I4-I5 -> 25704.26 | ... K6: =K4-K5 -> 25839.45 | L6: =SUM(Quarters!H6:K6) -> 26913.07 | M6: =M4*M24 -> 29921.955 | N6: =N4*N24 -> 27417.048
A7: Other Income | B7: ='Data Sheet'!B25 -> 1483.11 | C7: ='Data Sheet'!C25 -> 1758.63 | D7: ='Data Sheet'!D25 -> 2239.81 | E7: ='Data Sheet'!E25 -> 2080.44 | F7: ='Data Sheet'!F25 -> 2417.32 | G7: ='Data Sheet'!G25 -> 2576.95 | H7: ='Data Sheet'!H25 -> 1909.72 | I7: ='Data Sheet'!I25 -> 2097.64 | ... K7: ='Data Sheet'!K25 -> 17794.88 | L7: =SUM(Quarters!H7:K7) -> 17202.94 | M7: 0 | N7: 0
A8: Depreciation | B8: ='Data Sheet'!B26 -> 1077.4 | C8: ='Data Sheet'!C26 -> 1152.79 | D8: ='Data Sheet'!D26 -> 1236.28 | E8: ='Data Sheet'!E26 -> 1396.61 | F8: ='Data Sheet'!F26 -> 1644.91 | G8: ='Data Sheet'!G26 -> 1645.59 | H8: ='Data Sheet'!H26 -> 1732.41 | I8: ='Data Sheet'!I26 -> 1809.01 | ... K8: ='Data Sheet'!K26 -> 1646.32 | L8: =SUM(Quarters!H8:K8) -> 1699.61 | M8: =+$L8 -> 1699.61 | N8: =+$L8 -> 1699.61
A9: Interest | B9: ='Data Sheet'!B27 -> 78.13 | C9: ='Data Sheet'!C27 -> 49.03 | D9: ='Data Sheet'!D27 -> 115.01 | E9: ='Data Sheet'!E27 -> 71.4 | F9: ='Data Sheet'!F27 -> 81.38 | G9: ='Data Sheet'!G27 -> 57.97 | H9: ='Data Sheet'!H27 -> 59.99 | I9: ='Data Sheet'!I27 -> 77.77 | ... K9: ='Data Sheet'!K27 -> 45.06 | L9: =SUM(Quarters!H9:K9) -> 66.9 | M9: =+$L9 -> 66.9 | N9: =+$L9 -> 66.9
A10: Profit before tax | B10: ='Data Sheet'!B28 -> 14859.07 | C10: ='Data Sheet'!C28 -> 16026.32 | D10: ='Data Sheet'!D28 -> 17409.11 | E10: ='Data Sheet'!E28 -> 19149.82 | F10: ='Data Sheet'!F28 -> 20034.57 | G10: ='Data Sheet'!G28 -> 17938.17 | H10: ='Data Sheet'!H28 -> 20740.47 | I10: ='Data Sheet'!I28 -> 25915.12 | ... K10: ='Data Sheet'!K28 -> 41942.95 | L10: =SUM(Quarters!H10:K10) -> 42349.5 | M10: =M6+M7-SUM(M8:M9) -> 28155.445 | N10: =N6+N7-SUM(N8:N9) -> 25650.538
A11: Tax | B11: ='Data Sheet'!B29 -> 5358.21 | C11: ='Data Sheet'!C29 -> 5549.09 | D11: ='Data Sheet'!D29 -> 5916.43 | E11: ='Data Sheet'!E29 -> 6313.92 | F11: ='Data Sheet'!F29 -> 4441.79 | G11: ='Data Sheet'!G29 -> 4555.29 | H11: ='Data Sheet'!H29 -> 5237.34 | I11: ='Data Sheet'!I29 -> 6438.4 | ... K11: ='Data Sheet'!K29 -> 6890.47 | L11: =SUM(Quarters!H11:K11) -> 6993.21 | M11: =IF($L10>0,$L11/$L10,0) -> 0.16513088 | N11: =IF($L10>0,$L11/$L10,0) -> 0.16513088
A12: Net profit | B12: ='Data Sheet'!B30 -> 9344.45 | C12: ='Data Sheet'!C30 -> 10289.44 | D12: ='Data Sheet'!D30 -> 11271.2 | E12: ='Data Sheet'!E30 -> 12592.33 | F12: ='Data Sheet'!F30 -> 15306.23 | G12: ='Data Sheet'!G30 -> 13161.19 | H12: ='Data Sheet'!H30 -> 15242.66 | I12: ='Data Sheet'!I30 -> 19191.66 | ... K12: ='Data Sheet'!K30 -> 34746.63 | L12: =SUM(Quarters!H12:K12) -> 35028.87 | M12: =M10-M11*M10 -> 23506.111 | N12: =N10-N11*N10 -> 21414.842
A13: EPS | B13: =IF('Data Sheet'!B93>0,B12/'Data Sheet'!B93,0) -> 7.7413676 | C13: =IF('Data Sheet'!C93>0,C12/'Data Sheet'!C93,0) -> 8.4704875 | D13: =IF('Data Sheet'!D93>0,D12/'Data Sheet'!D93,0) -> 9.2354334 | E13: =IF('Data Sheet'!E93>0,E12/'Data Sheet'!E93,0) -> 10.272242 | F13: =IF('Data Sheet'!F93>0,F12/'Data Sheet'!F93,0) -> 12.451986 | G13: =IF('Data Sheet'!G93>0,G12/'Data Sheet'!G93,0) -> 10.692505 | H13: =IF('Data Sheet'!H93>0,H12/'Data Sheet'!H93,0) -> 12.368976 | I13: =IF('Data Sheet'!I93>0,I12/'Data Sheet'!I93,0) -> 15.442276 | ... K13: =IF('Data Sheet'!K93>0,K12/'Data Sheet'!K93,0) -> 27.765984 | L13: =IF('Data Sheet'!$B6>0,'Profit & Loss'!L12/'Data Sheet'!$B6,0) -> 27.957188 | M13: =IF('Data Sheet'!$B6>0,'Profit & Loss'!M12/'Data Sheet'!$B6,0) -> 18.760662 | N13: =IF('Data Sheet'!$B6>0,'Profit & Loss'!N12/'Data Sheet'!$B6,0) -> 17.091581
A14: Price to earning | B14: =IF(B15>0,B15/B13,"") -> 26.497902 | C14: =IF(C15>0,C15/C13,"") -> 31.019466 | D14: =IF(D15>0,D15/D13,"") -> 25.93273 | E14: =IF(E15>0,E15/E13,"") -> 27.12553 | F14: =IF(F15>0,F15/F13,"") -> 12.925649 | G14: =IF(G15>0,G15/G13,"") -> 19.155475 | H14: =IF(H15>0,H15/H13,"") -> 18.995914 | I14: =IF(I15>0,I15/I13,"") -> 23.2796 | ... K14: =IF(K15>0,K15/K13,"") -> 14.757266 | L14: =IF(L13>0,L15/L13,0) -> 10.997172 | M14: =M25 -> 18.384219 | N14: =N25 -> 10.997172
A15: Price | B15: ='Data Sheet'!B90 -> 205.13 | C15: ='Data Sheet'!C90 -> 262.75 | D15: ='Data Sheet'!D90 -> 239.5 | E15: ='Data Sheet'!E90 -> 278.64 | F15: ='Data Sheet'!F90 -> 160.95 | G15: ='Data Sheet'!G90 -> 204.82 | H15: ='Data Sheet'!H90 -> 234.96 | I15: ='Data Sheet'!I90 -> 359.49 | ... K15: ='Data Sheet'!K90 -> 409.75 | L15: ='Data Sheet'!B8 -> 307.45 | M15: =M13*M14 -> 344.90011 | N15: =N13*N14 -> 187.95906
A17: RATIOS:
A18: Dividend Payout | B18: =IF('Data Sheet'!B30>0, 'Data Sheet'!B31/'Data Sheet'!B30, 0) -> 0.73199814 | C18: =IF('Data Sheet'!C30>0, 'Data Sheet'!C31/'Data Sheet'!C30, 0) -> 0.56077104 | D18: =IF('Data Sheet'!D30>0, 'Data Sheet'!D31/'Data Sheet'!D30, 0) -> 0.5576345 | E18: =IF('Data Sheet'!E30>0, 'Data Sheet'!E31/'Data Sheet'!E30, 0) -> 0.55976138 | F18: =IF('Data Sheet'!F30>0, 'Data Sheet'!F31/'Data Sheet'!F30, 0) -> 0.81513083 | G18: =IF('Data Sheet'!G30>0, 'Data Sheet'!G31/'Data Sheet'!G30, 0) -> 1.0053772 | H18: =IF('Data Sheet'!H30>0, 'Data Sheet'!H31/'Data Sheet'!H30, 0) -> 0.92974586 | I18: =IF('Data Sheet'!I30>0, 'Data Sheet'!I31/'Data Sheet'!I30, 0) -> 1.0037381 | ... K18: =IF('Data Sheet'!K30>0, 'Data Sheet'!K31/'Data Sheet'!K30, 0) -> 0.51681933
A19: OPM | B19: =IF(B6>0,B6/B4,0) -> 0.370776 | C19: =IF(C6>0,C6/C4,0) -> 0.36171097 | D19: =IF(D6>0,D6/D4,0) -> 0.38022999 | E19: =IF(E6>0,E6/E4,0) -> 0.38348265 | F19: =IF(F6>0,F6/F4,0) -> 0.39166716 | G19: =IF(G6>0,G6/G4,0) -> 0.34644059 | H19: =IF(H6>0,H6/H4,0) -> 0.34006606 | I19: =IF(I6>0,I6/I4,0) -> 0.36244517 | ... L19: =IF(L6>0,L6/L4,0) -> 0.33721967
G22: TRENDS: | H22: 10 YEARS | I22: 7 YEARS | J22: 5 YEARS | K22: 3 YEARS | L22: RECENT | M22: BEST | N22: WORST
G23: Sales Growth | H23: =IF(B4=0,"",POWER($K4/B4,1/9)-1) -> 0.075290157 | I23: =IF(D4=0,"",POWER($K4/D4,1/7)-1) -> 0.081772082 | J23: =IF(F4=0,"",POWER($K4/F4,1/5)-1) -> 0.088083322 | K23: =IF(H4=0,"",POWER($K4/H4, 1/3)-1) -> 0.074927782 | L23: =IF(ISERROR(MAX(IF(J4=0,"",(K4-J4)/J4),IF(K4=0,"",(L4-K4)/K4))),"",MAX(IF(J4=0,"",(K4-J4)/J4),IF(K4=0,"",(L4-K4)/K4))) -> 0.10880596 | M23: =MAX(K23:L23) -> 0.10880596 | N23: =MIN(H23:L23) -> 0.074927782
G24: OPM | H24: =IF(SUM(B4:$K$4)=0,"",SUMPRODUCT(B19:$K$19,B4:$K$4)/SUM(B4:$K$4)) -> 0.36333562 | I24: =IF(SUM(E4:$K$4)=0,"",SUMPRODUCT(E19:$K$19,E4:$K$4)/SUM(E4:$K$4)) -> 0.36106877 | J24: =IF(SUM(G4:$K$4)=0,"",SUMPRODUCT(G19:$K$19,G4:$K$4)/SUM(G4:$K$4)) -> 0.35306244 | K24: =IF(SUM(I4:$K$4)=0, "", SUMPRODUCT(I19:$K$19,I4:$K$4)/SUM(I4:$K$4)) -> 0.35826538 | L24: =L19 -> 0.33721967 | M24: =MAX(K24:L24) -> 0.35826538 | N24: =MIN(H24:L24) -> 0.33721967
G25: Price to Earning | H25: =IF(ISERROR(AVERAGEIF(B14:$L14,">0")),"",AVERAGEIF(B14:$L14,">0")) -> 21.380867 | I25: =IF(ISERROR(AVERAGEIF(E14:$L14,">0")),"",AVERAGEIF(E14:$L14,">0")) -> 18.96743 | J25: =IF(ISERROR(AVERAGEIF(G14:$L14,">0")),"",AVERAGEIF(G14:$L14,">0")) -> 18.614711 | K25: =IF(ISERROR(AVERAGEIF(I14:$L14,">0")),"",AVERAGEIF(I14:$L14,">0")) -> 18.384219 | L25: =L14 -> 10.997172 | M25: =MAX(K25:L25) -> 18.384219 | N25: =MIN(H25:L25) -> 10.997172

Sheet Quarters
A1: ='Profit & Loss'!A1 -> ITC LTD | E1: =UPDATE | J1: SCREENER.IN
A3: Narration | B3: ='Data Sheet'!B41 -> 45199 | C3: ='Data Sheet'!C41 -> 45291 | D3: ='Data Sheet'!D41 -> 45382 | E3: ='Data Sheet'!E41 -> 45473 | F3: ='Data Sheet'!F41 -> 45565 | G3: ='Data Sheet'!G41 -> 45657 | H3: ='Data Sheet'!H41 -> 45747 | I3: ='Data Sheet'!I41 -> 45838 | ... K3: ='Data Sheet'!K41 -> 46022
A4: Sales | B4: ='Data Sheet'!B42 -> 17774.47 | C4: ='Data Sheet'!C42 -> 17195.24 | D4: ='Data Sheet'!D42 -> 17037.8 | E4: ='Data Sheet'!E42 -> 17777.81 | F4: ='Data Sheet'!F42 -> 19990.36 | G4: ='Data Sheet'!G42 -> 18790.17 | H4: ='Data Sheet'!H42 -> 18765 | I4: ='Data Sheet'!I42 -> 21494.79 | ... K4: ='Data Sheet'!K42 -> 20047.3
A5: Expenses | B5: ='Data Sheet'!B43 -> 11320.23 | C5: ='Data Sheet'!C43 -> 10985.01 | D5: ='Data Sheet'!D43 -> 10735.73 | E5: ='Data Sheet'!E43 -> 11232.97 | F5: ='Data Sheet'!F43 -> 13438.28 | G5: ='Data Sheet'!G43 -> 12428.27 | H5: ='Data Sheet'!H43 -> 12245.61 | I5: ='Data Sheet'!I43 -> 14678.32 | ... K5: ='Data Sheet'!K43 -> 13164.78
A6: Operating Profit | B6: ='Data Sheet'!B50 -> 6454.24 | C6: ='Data Sheet'!C50 -> 6210.23 | D6: ='Data Sheet'!D50 -> 6302.07 | E6: ='Data Sheet'!E50 -> 6544.84 | F6: ='Data Sheet'!F50 -> 6552.08 | G6: ='Data Sheet'!G50 -> 6361.9 | H6: ='Data Sheet'!H50 -> 6519.39 | I6: ='Data Sheet'!I50 -> 6816.47 | ... K6: ='Data Sheet'!K50 -> 6882.52
A7: Other Income | B7: ='Data Sheet'!B44 -> 673.5 | C7: ='Data Sheet'!C44 -> 820.26 | D7: ='Data Sheet'!D44 -> 868 | E7: ='Data Sheet'!E44 -> 771.13 | F7: ='Data Sheet'!F44 -> 690.31 | G7: ='Data Sheet'!G44 -> 803.4 | H7: ='Data Sheet'!H44 -> 15391.28 | I7: ='Data Sheet'!I44 -> 750.97 | ... K7: ='Data Sheet'!K44 -> 321.85
A8: Depreciation | B8: ='Data Sheet'!B45 -> 453.04 | C8: ='Data Sheet'!C45 -> 384.04 | D8: ='Data Sheet'!D45 -> 385.09 | E8: ='Data Sheet'!E45 -> 403.13 | F8: ='Data Sheet'!F45 -> 416.18 | G8: ='Data Sheet'!G45 -> 415.98 | H8: ='Data Sheet'!H45 -> 411.03 | I8: ='Data Sheet'!I45 -> 422.96 | ... K8: ='Data Sheet'!K45 -> 430.82
A9: Interest | B9: ='Data Sheet'!B46 -> 9.87 | C9: ='Data Sheet'!C46 -> 11.94 | D9: ='Data Sheet'!D46 -> 10.72 | E9: ='Data Sheet'!E46 -> 9.6 | F9: ='Data Sheet'!F46 -> 14.73 | G9: ='Data Sheet'!G46 -> 9.82 | H9: ='Data Sheet'!H46 -> 10.91 | I9: ='Data Sheet'!I46 -> 16.47 | ... K9: ='Data Sheet'!K46 -> 19.47
A10: Profit before tax | B10: ='Data Sheet'!B47 -> 6664.83 | C10: ='Data Sheet'!C47 -> 6634.51 | D10: ='Data Sheet'!D47 -> 6774.26 | E10: ='Data Sheet'!E47 -> 6903.24 | F10: ='Data Sheet'!F47 -> 6811.48 | G10: ='Data Sheet'!G47 -> 6739.5 | H10: ='Data Sheet'!H47 -> 21488.73 | I10: ='Data Sheet'!I47 -> 7128.01 | ... K10: ='Data Sheet'!K47 -> 6754.08
A11: Tax | B11: ='Data Sheet'!B48 -> 1700.31 | C11: ='Data Sheet'!C48 -> 1227.99 | D11: ='Data Sheet'!D48 -> 1583.55 | E11: ='Data Sheet'!E48 -> 1726.25 | F11: ='Data Sheet'!F48 -> 1757.05 | G11: ='Data Sheet'!G48 -> 1726.32 | H11: ='Data Sheet'!H48 -> 1680.85 | I11: ='Data Sheet'!I48 -> 1784.6 | ... K11: ='Data Sheet'!K48 -> 1735.63
A12: Net profit | B12: ='Data Sheet'!B49 -> 4898.07 | C12: ='Data Sheet'!C49 -> 5335.23 | D12: ='Data Sheet'!D49 -> 5120.55 | E12: ='Data Sheet'!E49 -> 5091.59 | F12: ='Data Sheet'!F49 -> 4992.87 | G12: ='Data Sheet'!G49 -> 4934.8 | H12: ='Data Sheet'!H49 -> 19727.37 | I12: ='Data Sheet'!I49 -> 5244.2 | ... K12: ='Data Sheet'!K49 -> 4931.19
A14: OPM | B14: =IF(B4>0,B6/B4,"") -> 0.36311856 | C14: =IF(C4>0,C6/C4,"") -> 0.36115983 | D14: =IF(D4>0,D6/D4,"") -> 0.36988754 | E14: =IF(E4>0,E6/E4,"") -> 0.36814658 | F14: =IF(F4>0,F6/F4,"") -> 0.32776198 | G14: =IF(G4>0,G6/G4,"") -> 0.33857597 | H14: =IF(H4>0,H6/H4,"") -> 0.34742286 | I14: =IF(I4>0,I6/I4,"") -> 0.31712196 | ... K14: =IF(K4>0,K6/K4,"") -> 0.34331406

Sheet Balance Sheet
A1: ='Profit & Loss'!A1 -> ITC LTD | E1: =UPDATE | J1: SCREENER.IN
A3: Narration | B3: ='Data Sheet'!B56 -> 42460 | C3: ='Data Sheet'!C56 -> 42825 | D3: ='Data Sheet'!D56 -> 43190 | E3: ='Data Sheet'!E56 -> 43555 | F3: ='Data Sheet'!F56 -> 43921 | G3: ='Data Sheet'!G56 -> 44286 | H3: ='Data Sheet'!H56 -> 44651 | I3: ='Data Sheet'!I56 -> 45016 | ... K3: ='Data Sheet'!K56 -> 45747
A4: Equity Share Capital | B4: ='Data Sheet'!B57 -> 804.72 | C4: ='Data Sheet'!C57 -> 1214.74 | D4: ='Data Sheet'!D57 -> 1220.43 | E4: ='Data Sheet'!E57 -> 1225.86 | F4: ='Data Sheet'!F57 -> 1229.22 | G4: ='Data Sheet'!G57 -> 1230.88 | H4: ='Data Sheet'!H57 -> 1232.33 | I4: ='Data Sheet'!I57 -> 1242.8 | ... K4: ='Data Sheet'!K57 -> 1251.41
A5: Reserves | B5: ='Data Sheet'!B58 -> 41874.8 | C5: ='Data Sheet'!C58 -> 45198.19 | D5: ='Data Sheet'!D58 -> 51289.68 | E5: ='Data Sheet'!E58 -> 57915.01 | F5: ='Data Sheet'!F58 -> 64044.04 | G5: ='Data Sheet'!G58 -> 59116.46 | H5: ='Data Sheet'!H58 -> 61223.24 | I5: ='Data Sheet'!I58 -> 67912.46 | ... K5: ='Data Sheet'!K58 -> 68778.64
A6: Borrowings | B6: ='Data Sheet'!B59 -> 83.78 | C6: ='Data Sheet'!C59 -> 45.72 | D6: ='Data Sheet'!D59 -> 35.92 | E6: ='Data Sheet'!E59 -> 13.44 | F6: ='Data Sheet'!F59 -> 277.45 | G6: ='Data Sheet'!G59 -> 270.83 | H6: ='Data Sheet'!H59 -> 249.44 | I6: ='Data Sheet'!I59 -> 306.04 | ... K6: ='Data Sheet'!K59 -> 284.54
A7: Other Liabilities | B7: ='Data Sheet'!B60 -> 8888.04 | C7: ='Data Sheet'!C60 -> 9439.67 | D7: ='Data Sheet'!D60 -> 11694.85 | E7: ='Data Sheet'!E60 -> 12584.73 | F7: ='Data Sheet'!F60 -> 11760.04 | G7: ='Data Sheet'!G60 -> 13142.59 | H7: ='Data Sheet'!H60 -> 14491.01 | I7: ='Data Sheet'!I60 -> 16369.66 | ... K7: ='Data Sheet'!K60 -> 17688.11
A8: Total | B8: ='Data Sheet'!B61 -> 51651.34 | C8: ='Data Sheet'!C61 -> 55898.32 | D8: ='Data Sheet'!D61 -> 64240.88 | E8: ='Data Sheet'!E61 -> 71739.04 | F8: ='Data Sheet'!F61 -> 77310.75 | G8: ='Data Sheet'!G61 -> 73760.76 | H8: ='Data Sheet'!H61 -> 77196.02 | I8: ='Data Sheet'!I61 -> 85830.96 | ... K8: ='Data Sheet'!K61 -> 88002.7
A10: Net Block | B10: ='Data Sheet'!B62 -> 15106.63 | C10: ='Data Sheet'!C62 -> 15893.48 | D10: ='Data Sheet'!D62 -> 16523.96 | E10: ='Data Sheet'!E62 -> 19374.19 | F10: ='Data Sheet'!F62 -> 21713.34 | G10: ='Data Sheet'!G62 -> 23298.48 | H10: ='Data Sheet'!H62 -> 24231.59 | I10: ='Data Sheet'!I62 -> 25851.27 | ... K10: ='Data Sheet'!K62 -> 21954.85
A11: Capital Work in Progress | B11: ='Data Sheet'!B63 -> 2559.72 | C11: ='Data Sheet'!C63 -> 3729.89 | D11: ='Data Sheet'!D63 -> 5508.33 | E11: ='Data Sheet'!E63 -> 4136.42 | F11: ='Data Sheet'!F63 -> 3256.46 | G11: ='Data Sheet'!G63 -> 4011.29 | H11: ='Data Sheet'!H63 -> 3225.54 | I11: ='Data Sheet'!I63 -> 3003.3 | ... K11: ='Data Sheet'!K63 -> 1090.91
A12: Investments | B12: ='Data Sheet'!B64 -> 11747.59 | C12: ='Data Sheet'!C64 -> 17581.38 | D12: ='Data Sheet'!D64 -> 22052.86 | E12: ='Data Sheet'!E64 -> 25043.49 | F12: ='Data Sheet'!F64 -> 28663.35 | G12: ='Data Sheet'!G64 -> 24870.87 | H12: ='Data Sheet'!H64 -> 24841.01 | I12: ='Data Sheet'!I64 -> 29415.02 | ... K12: ='Data Sheet'!K64 -> 34719.82
A13: Other Assets | B13: ='Data Sheet'!B65 -> 22237.4 | C13: ='Data Sheet'!C65 -> 18693.57 | D13: ='Data Sheet'!D65 -> 20155.73 | E13: ='Data Sheet'!E65 -> 23184.94 | F13: ='Data Sheet'!F65 -> 23677.6 | G13: ='Data Sheet'!G65 -> 21580.12 | H13: ='Data Sheet'!H65 -> 24897.88 | I13: ='Data Sheet'!I65 -> 27561.37 | ... K13: ='Data Sheet'!K65 -> 30237.12
A14: Total | B14: ='Data Sheet'!B66 -> 51651.34 | C14: ='Data Sheet'!C66 -> 55898.32 | D14: ='Data Sheet'!D66 -> 64240.88 | E14: ='Data Sheet'!E66 -> 71739.04 | F14: ='Data Sheet'!F66 -> 77310.75 | G14: ='Data Sheet'!G66 -> 73760.76 | H14: ='Data Sheet'!H66 -> 77196.02 | I14: ='Data Sheet'!I66 -> 85830.96 | ... K14: ='Data Sheet'!K66 -> 88002.7
A16: Working Capital | B16: =B13-B7 -> 13349.36 | C16: =C13-C7 -> 9253.9 | D16: =D13-D7 -> 8460.88 | E16: =E13-E7 -> 10600.21 | F16: =F13-F7 -> 11917.56 | G16: =G13-G7 -> 8437.53 | H16: =H13-H7 -> 10406.87 | I16: =I13-I7 -> 11191.71 | ... K16: =K13-K7 -> 12549.01
A17: Debtors | B17: ='Data Sheet'!B67 -> 1917.18 | C17: ='Data Sheet'!C67 -> 2474.29 | D17: ='Data Sheet'!D67 -> 2682.29 | E17: ='Data Sheet'!E67 -> 4035.28 | F17: ='Data Sheet'!F67 -> 2562.48 | G17: ='Data Sheet'!G67 -> 2501.7 | H17: ='Data Sheet'!H67 -> 2461.9 | I17: ='Data Sheet'!I67 -> 2956.17 | ... K17: ='Data Sheet'!K67 -> 4719.67
A18: Inventory | B18: ='Data Sheet'!B68 -> 9062.1 | C18: ='Data Sheet'!C68 -> 8116.1 | D18: ='Data Sheet'!D68 -> 7495.09 | E18: ='Data Sheet'!E68 -> 7859.56 | F18: ='Data Sheet'!F68 -> 8879.33 | G18: ='Data Sheet'!G68 -> 10397.16 | H18: ='Data Sheet'!H68 -> 10864.15 | I18: ='Data Sheet'!I68 -> 11771.16 | ... K18: ='Data Sheet'!K68 -> 15637.56
A20: Debtor Days | B20: =IF('Profit & Loss'!B4>0,'Balance Sheet'!B17/('Profit & Loss'!B4/365),0) -> 17.854892 | C20: =IF('Profit & Loss'!C4>0,'Balance Sheet'!C17/('Profit & Loss'!C4/365),0) -> 21.116823 | D20: =IF('Profit & Loss'!D4>0,'Balance Sheet'!D17/('Profit & Loss'!D4/365),0) -> 22.53302 | E20: =IF('Profit & Loss'!E4>0,'Balance Sheet'!E17/('Profit & Loss'!E4/365),0) -> 30.469383 | F20: =IF('Profit & Loss'!F4>0,'Balance Sheet'!F17/('Profit & Loss'!F4/365),0) -> 18.938019 | G20: =IF('Profit & Loss'!G4>0,'Balance Sheet'!G17/('Profit & Loss'!G4/365),0) -> 18.537714 | H20: =IF('Profit & Loss'!H4>0,'Balance Sheet'!H17/('Profit & Loss'!H4/365),0) -> 14.817385 | I20: =IF('Profit & Loss'!I4>0,'Balance Sheet'!I17/('Profit & Loss'!I4/365),0) -> 15.214563 | ... K20: =IF('Profit & Loss'!K4>0,'Balance Sheet'!K17/('Profit & Loss'!K4/365),0) -> 22.870462
A21: Inventory Turnover | B21: =IF('Balance Sheet'!B18>0,'Profit & Loss'!B4/'Balance Sheet'!B18,0) -> 4.3248364 | C21: =IF('Balance Sheet'!C18>0,'Profit & Loss'!C4/'Balance Sheet'!C18,0) -> 5.2694767 | D21: =IF('Balance Sheet'!D18>0,'Profit & Loss'!D4/'Balance Sheet'!D18,0) -> 5.7969871 | E21: =IF('Balance Sheet'!E18>0,'Profit & Loss'!E4/'Balance Sheet'!E18,0) -> 6.1504181 | F21: =IF('Balance Sheet'!F18>0,'Profit & Loss'!F4/'Balance Sheet'!F18,0) -> 5.5620976 | G21: =IF('Balance Sheet'!G18>0,'Profit & Loss'!G4/'Balance Sheet'!G18,0) -> 4.737587 | H21: =IF('Balance Sheet'!H18>0,'Profit & Loss'!H4/'Balance Sheet'!H18,0) -> 5.5820787 | I21: =IF('Balance Sheet'!I18>0,'Profit & Loss'!I4/'Balance Sheet'!I18,0) -> 6.0248123 | ... K21: =IF('Balance Sheet'!K18>0,'Profit & Loss'!K4/'Balance Sheet'!K18,0) -> 4.8168218
A23: Return on Equity | B23: =IF(SUM('Balance Sheet'!B4:B5)>0,'Profit & Loss'!B12/SUM('Balance Sheet'!B4:B5),"") -> 0.21894459 | C23: =IF(SUM('Balance Sheet'!C4:C5)>0,'Profit & Loss'!C12/SUM('Balance Sheet'!C4:C5),"") -> 0.22169339 | D23: =IF(SUM('Balance Sheet'!D4:D5)>0,'Profit & Loss'!D12/SUM('Balance Sheet'!D4:D5),"") -> 0.21464819 | E23: =IF(SUM('Balance Sheet'!E4:E5)>0,'Profit & Loss'!E12/SUM('Balance Sheet'!E4:E5),"") -> 0.21292095 | F23: =IF(SUM('Balance Sheet'!F4:F5)>0,'Profit & Loss'!F12/SUM('Balance Sheet'!F4:F5),"") -> 0.23449465 | G23: =IF(SUM('Balance Sheet'!G4:G5)>0,'Profit & Loss'!G12/SUM('Balance Sheet'!G4:G5),"") -> 0.21809064 | H23: =IF(SUM('Balance Sheet'!H4:H5)>0,'Profit & Loss'!H12/SUM('Balance Sheet'!H4:H5),"") -> 0.24405605 | I23: =IF(SUM('Balance Sheet'!I4:I5)>0,'Profit & Loss'!I12/SUM('Balance Sheet'!I4:I5),"") -> 0.27751555 | ... K23: =IF(SUM('Balance Sheet'!K4:K5)>0,'Profit & Loss'!K12/SUM('Balance Sheet'!K4:K5),"") -> 0.49616743
A24: Return on Capital Emp | C24: =IF((B4+B5+B6+C4+C5+C6)>0,('Profit & Loss'!C10+'Profit & Loss'!C9)*2/(B4+B5+B6+C4+C5+C6),"") -> 0.36034518 | D24: =IF((C4+C5+C6+D4+D5+D6)>0,('Profit & Loss'!D10+'Profit & Loss'!D9)*2/(C4+C5+C6+D4+D5+D6),"") -> 0.35400589 | E24: =IF((D4+D5+D6+E4+E5+E6)>0,('Profit & Loss'!E10+'Profit & Loss'!E9)*2/(D4+D5+D6+E4+E5+E6),"") -> 0.34415688 | F24: =IF((E4+E5+E6+F4+F5+F6)>0,('Profit & Loss'!F10+'Profit & Loss'!F9)*2/(E4+E5+E6+F4+F5+F6),"") -> 0.32261652 | G24: =IF((F4+F5+F6+G4+G5+G6)>0,('Profit & Loss'!G10+'Profit & Loss'!G9)*2/(F4+F5+F6+G4+G5+G6),"") -> 0.28527066 | H24: =IF((G4+G5+G6+H4+H5+H6)>0,('Profit & Loss'!H10+'Profit & Loss'!H9)*2/(G4+G5+G6+H4+H5+H6),"") -> 0.33733253 | I24: =IF((H4+H5+H6+I4+I5+I6)>0,('Profit & Loss'!I10+'Profit & Loss'!I9)*2/(H4+H5+H6+I4+I5+I6),"") -> 0.39333609 | J24: =IF((I4+I5+I6+J4+J5+J6)>0,('Profit & Loss'!J10+'Profit & Loss'!J9)*2/(I4+I5+I6+J4+J5+J6),"") -> 0.37429273 | K24: =IF((J4+J5+J6+K4+K5+K6)>0,('Profit & Loss'!K10+'Profit & Loss'!K9)*2/(J4+J5+J6+K4+K5+K6),"") -> 0.57864605

Sheet Cash Flow
A1: ='Balance Sheet'!A1 -> ITC LTD | E1: =UPDATE | J1: SCREENER.IN
A3: Narration | B3: ='Data Sheet'!B81 -> 42460 | C3: ='Data Sheet'!C81 -> 42825 | D3: ='Data Sheet'!D81 -> 43190 | E3: ='Data Sheet'!E81 -> 43555 | F3: ='Data Sheet'!F81 -> 43921 | G3: ='Data Sheet'!G81 -> 44286 | H3: ='Data Sheet'!H81 -> 44651 | I3: ='Data Sheet'!I81 -> 45016 | ... K3: ='Data Sheet'!K81 -> 45747
A4: Cash from Operating Activity | B4: ='Data Sheet'!B82 -> 9799.04 | C4: ='Data Sheet'!C82 -> 10627.31 | D4: ='Data Sheet'!D82 -> 13169.4 | E4: ='Data Sheet'!E82 -> 12583.41 | F4: ='Data Sheet'!F82 -> 14689.66 | G4: ='Data Sheet'!G82 -> 12526.97 | H4: ='Data Sheet'!H82 -> 15775.51 | I4: ='Data Sheet'!I82 -> 18877.55 | ... K4: ='Data Sheet'!K82 -> 17627.04
A5: Cash from Investing Activity | B5: ='Data Sheet'!B83 -> -3920.73 | C5: ='Data Sheet'!C83 -> -3250.93 | D5: ='Data Sheet'!D83 -> -7113.89 | E5: ='Data Sheet'!E83 -> -5545.68 | F5: ='Data Sheet'!F83 -> -6174.02 | G5: ='Data Sheet'!G83 -> 5739.98 | H5: ='Data Sheet'!H83 -> -2238.49 | I5: ='Data Sheet'!I83 -> -5732.29 | ... K5: ='Data Sheet'!K83 -> -563.84
A6: Cash from Financing Activity | B6: ='Data Sheet'!B84 -> -5612.52 | C6: ='Data Sheet'!C84 -> -7301.03 | D6: ='Data Sheet'!D84 -> -6221.13 | E6: ='Data Sheet'!E84 -> -6868.64 | F6: ='Data Sheet'!F84 -> -8181.48 | G6: ='Data Sheet'!G84 -> -18633.83 | H6: ='Data Sheet'!H84 -> -13580.5 | I6: ='Data Sheet'!I84 -> -13006.03 | ... K6: ='Data Sheet'!K84 -> -17037.4
A7: Net Cash Flow | B7: ='Data Sheet'!B85 -> 265.79 | C7: ='Data Sheet'!C85 -> 75.35 | D7: ='Data Sheet'!D85 -> -165.62 | E7: ='Data Sheet'!E85 -> 169.09 | F7: ='Data Sheet'!F85 -> 334.16 | G7: ='Data Sheet'!G85 -> -366.88 | H7: ='Data Sheet'!H85 -> -43.48 | I7: ='Data Sheet'!I85 -> 139.23 | ... K7: ='Data Sheet'!K85 -> 25.8

Sheet Data Sheet
A1: COMPANY NAME | B1: ITC LTD | E1: =IF(B2<>B3, "A NEW VERSION OF THE WORKSHEET IS AVAILABLE", "")
A2: LATEST VERSION | B2: 2.1 | E2: PLEASE DO NOT MAKE ANY CHANGES TO THIS SHEET
A3: CURRENT VERSION | B3: 2.1
A5: META
A6: Number of shares | B6: =IF(B9>0, B9/B8, 0) -> 1252.9468
A7: Face Value | B7: 1
A8: Current Price | B8: 307.45
A9: Market Capitalization | B9: 385218.5
A15: PROFIT & LOSS
A16: Report Date | B16: 42460 | C16: 42825 | D16: 43190 | E16: 43555 | F16: 43921 | G16: 44286 | H16: 44651 | I16: 45016 | J16: 45382 | K16: 45747
A17: Sales | B17: 39192.1 | C17: 42767.6 | D17: 43448.94 | E17: 48339.58 | F17: 49387.7 | G17: 49257.45 | H17: 60644.54 | I17: 70919.03 | J17: 67931.94 | K17: 75323.34
A18: Raw Material Cost | B18: 13763.88 | C18: 15456.59 | D18: 14827.72 | E18: 17623.52 | F18: 18048.6 | G18: 20776.71 | H18: 27071.07 | I18: 29364.36 | J18: 27348.57 | K18: 32704.37
A19: Change in Inventory | B19: 195.38 | C19: -592.57 | D19: -1027.76 | E19: 203.19 | F19: 703.13 | G19: 645.27 | H19: 686 | I19: 358.59 | J19: 367.77 | K19: 725.65
A20: Power and Fuel | B20: 571.88 | C20: 584.33 | D20: 653.5 | E20: 746.73 | F20: 780.85 | G20: 699.56 | H20: 889.77 | I20: 1232.34 | J20: 952.9 | K20: 975.35
A21: Other Mfr. Exp | B21: 1581.59 | C21: 1683.9 | D21: 1697.62 | E21: 1871.01 | F21: 1908.29 | G21: 1587.18 | H21: 1887.67 | I21: 2327.8 | J21: 2183.76 | K21: 2345.36
A22: Employee Cost | B22: 3440.97 | C22: 3631.73 | D22: 3760.9 | E22: 4177.88 | F22: 4295.79 | G22: 4463.33 | H22: 4890.55 | I22: 5736.22 | J22: 5548.53 | K22: 6169.78
A23: Selling and admin | B23: 4261.78 | C23: 4179.74 | D23: 3954.87 | E23: 4546.39 | F23: 4488.63 | G23: 4236.77 | H23: 4858.38 | I23: 5604.08 | J23: 5312.45 | K23: 5793.29 | L23: =SUM(H23:K23) -> 21568.2 | M23: =SUM(L23,L24) -> 27974.07
A24: Other Expenses | B24: 1235.89 | C24: 1169.23 | D24: 1005.98 | E24: 1039.85 | F24: 1225.13 | G24: 1074.39 | H24: 1109.95 | I24: 1308.56 | J24: 1765.97 | K24: 2221.39 | L24: =SUM(H24:K24) -> 6405.87
A25: Other Income | B25: 1483.11 | C25: 1758.63 | D25: 2239.81 | E25: 2080.44 | F25: 2417.32 | G25: 2576.95 | H25: 1909.72 | I25: 2097.64 | J25: 3330.45 | K25: 17794.88
A26: Depreciation | B26: 1077.4 | C26: 1152.79 | D26: 1236.28 | E26: 1396.61 | F26: 1644.91 | G26: 1645.59 | H26: 1732.41 | I26: 1809.01 | J26: 1518.05 | K26: 1646.32
A27: Interest | B27: 78.13 | C27: 49.03 | D27: 115.01 | E27: 71.4 | F27: 81.38 | G27: 57.97 | H27: 59.99 | I27: 77.77 | J27: 39.11 | K27: 45.06
A28: Profit before tax | B28: 14859.07 | C28: 16026.32 | D28: 17409.11 | E28: 19149.82 | F28: 20034.57 | G28: 17938.17 | H28: 20740.47 | I28: 25915.12 | J28: 26960.82 | K28: 41942.95
A29: Tax | B29: 5358.21 | C29: 5549.09 | D29: 5916.43 | E29: 6313.92 | F29: 4441.79 | G29: 4555.29 | H29: 5237.34 | I29: 6438.4 | J29: 6209.46 | K29: 6890.47
A30: Net profit | B30: 9344.45 | C30: 10289.44 | D30: 11271.2 | E30: 12592.33 | F30: 15306.23 | G30: 13161.19 | H30: 15242.66 | I30: 19191.66 | J30: 20458.78 | K30: 34746.63
A31: Dividend Amount | B31: 6840.12 | C31: 5770.02 | D31: 6285.21 | E31: 7048.7 | F31: 12476.58 | G31: 13231.96 | H31: 14171.8 | I31: 19263.4 | J31: 17166.46 | K31: 17957.73
A40: Quarters
A41: Report Date | B41: 45199 | C41: 45291 | D41: 45382 | E41: 45473 | F41: 45565 | G41: 45657 | H41: 45747 | I41: 45838 | J41: 45930 | K41: 46022
A42: Sales | B42: 17774.47 | C42: 17195.24 | D42: 17037.8 | E42: 17777.81 | F42: 19990.36 | G42: 18790.17 | H42: 18765 | I42: 21494.79 | J42: 19501.63 | K42: 20047.3
A43: Expenses | B43: 11320.23 | C43: 10985.01 | D43: 10735.73 | E43: 11232.97 | F43: 13438.28 | G43: 12428.27 | H43: 12245.61 | I43: 14678.32 | J43: 12806.94 | K43: 13164.78
A44: Other Income | B44: 673.5 | C44: 820.26 | D44: 868 | E44: 771.13 | F44: 690.31 | G44: 803.4 | H44: 15391.28 | I44: 750.97 | J44: 738.84 | K44: 321.85
A45: Depreciation | B45: 453.04 | C45: 384.04 | D45: 385.09 | E45: 403.13 | F45: 416.18 | G45: 415.98 | H45: 411.03 | I45: 422.96 | J45: 434.8 | K45: 430.82
A46: Interest | B46: 9.87 | C46: 11.94 | D46: 10.72 | E46: 9.6 | F46: 14.73 | G46: 9.82 | H46: 10.91 | I46: 16.47 | J46: 20.05 | K46: 19.47
A47: Profit before tax | B47: 6664.83 | C47: 6634.51 | D47: 6774.26 | E47: 6903.24 | F47: 6811.48 | G47: 6739.5 | H47: 21488.73 | I47: 7128.01 | J47: 6978.68 | K47: 6754.08
A48: Tax | B48: 1700.31 | C48: 1227.99 | D48: 1583.55 | E48: 1726.25 | F48: 1757.05 | G48: 1726.32 | H48: 1680.85 | I48: 1784.6 | J48: 1792.13 | K48: 1735.63
A49: Net profit | B49: 4898.07 | C49: 5335.23 | D49: 5120.55 | E49: 5091.59 | F49: 4992.87 | G49: 4934.8 | H49: 19727.37 | I49: 5244.2 | J49: 5126.11 | K49: 4931.19
A50: Operating Profit | B50: 6454.24 | C50: 6210.23 | D50: 6302.07 | E50: 6544.84 | F50: 6552.08 | G50: 6361.9 | H50: 6519.39 | I50: 6816.47 | J50: 6694.69 | K50: 6882.52
A55: BALANCE SHEET
A56: Report Date | B56: 42460 | C56: 42825 | D56: 43190 | E56: 43555 | F56: 43921 | G56: 44286 | H56: 44651 | I56: 45016 | J56: 45382 | K56: 45747
A57: Equity Share Capital | B57: 804.72 | C57: 1214.74 | D57: 1220.43 | E57: 1225.86 | F57: 1229.22 | G57: 1230.88 | H57: 1232.33 | I57: 1242.8 | J57: 1248.47 | K57: 1251.41
A58: Reserves | B58: 41874.8 | C58: 45198.19 | D58: 51289.68 | E58: 57915.01 | F58: 64044.04 | G58: 59116.46 | H58: 61223.24 | I58: 67912.46 | J58: 73258.53 | K58: 68778.64
...

Sheet cash flow 
B2: 41699 | C2: 42064 | D2: 42430 | E2: 42795 | F2: 43160 | G2: 43525 | H2: 43891 | I2: 44256 | J2: 44621 | K2: 44986 | L2: 45352 | M2: 45717
B3: Cash from Operating Activity - | C3: 7344 | D3: 9843 | E3: 9799 | F3: 10627 | G3: 13169 | H3: 12583 | I3: 14690 | J3: 12527 | K3: 15776 | L3: 18878 | M3: 17179 | N3: 17627
B4: Profit from operations | C4: 13172 | D4: 14261 | E4: 15154 | F4: 16075 | G4: 17433 | H4: 18862 | I4: 19416 | J4: 17326 | K4: 20857 | L4: 26052 | M4: 26635 | N4: 26719
B5: Receivables | C5: -1546 | D5: 558 | E5: -207 | F5: -870 | G5: -964 | H5: -755 | I5: 1411 | J5: -66 | K5: -732 | L5: -884 | M5: -934 | N5: -1023
B6: Inventory | C6: -755 | D6: -505 | E6: -693 | F6: 593 | G6: 602 | H6: -359 | I6: -508 | J6: -1460 | K6: -466 | L6: -1098 | M6: -2545 | N6: -2975
B7: Payables | C7: 456 | D7: -23 | E7: 622 | F7: 321 | G7: 2098 | H7: 639 | I7: -607 | J7: 1112 | K7: 1099 | L7: 1058 | M7: 141 | N7: 1256
B8: Working capital changes | C8: -1844 | D8: 31 | E8: -277 | F8: 44 | G8: 1736 | H8: -476 | I8: 296 | J8: -413 | K8: -100 | L8: -924 | M8: -3337 | N8: -2742
B9: Direct taxes | C9: -3984 | D9: -4449 | E9: -5078 | F9: -5492 | G9: -6000 | H9: -5803 | I9: -5023 | J9: -4387 | K9: -4982 | L9: -6250 | M9: -6120 | N9: -6350
B10: Cash from Investing Activity - | C10: -3254 | D10: -5275 | E10: -3921 | F10: -3251 | G10: -7114 | H10: -5546 | I10: -6174 | J10: 5740 | K10: -2238 | L10: -5732 | M10: 1563 | N10: -564
B11: Fixed assets purchased | C11: -2887 | D11: -3300 | E11: -2348 | F11: -3122 | G11: -2878 | H11: -3169 | I11: -2441 | J11: -1837 | K11: -2142 | L11: -2743 | M11: -3563 | N11: -2279
B12: Fixed assets sold | C12: 38 | D12: 9 | E12: 8 | F12: 50 | G12: 80 | H12: 28 | I12: 27 | J12: 3 | K12: 133 | L12: 49 | M12: 107 | N12: 175
B13: Investments purchased | C13: -94242 | D13: -98742 | E13: -154081 | F13: -85683 | G13: -98330 | H13: -94187 | I13: -79835 | J13: -57553 | K13: -69776 | L13: -80932 | M13: -75107 | N13: -66373
B14: Investments sold | C14: 93293 | D14: 99658 | E14: 150651 | F14: 81034 | G14: 95017 | H14: 92454 | I14: 75835 | J14: 62797 | K14: 70992 | L14: 77230 | M14: 77830 | N14: 67311
... B34: CFO/OP | C34: 0.31 | D34: 0.43 | E34: 0.2 | F34: 0.25 | G34: -0.09 | H34: 0.08 | I34: 1.72 | J34: 0.74 | K34: -0.21 | L34: -0.07 | M34: 0.26 | N34: 0.48

Sheet historical sf 
A2: # | B2: =" historical fiancial statement " &'Data Sheet'!B1 -> historical fiancial statement ITC LTD
B4: years | C4: ='Data Sheet'!B16 -> 42460 | D4: ='Data Sheet'!C16 -> 42825 | E4: ='Data Sheet'!D16 -> 43190 | F4: ='Data Sheet'!E16 -> 43555 | G4: ='Data Sheet'!F16 -> 43921 | H4: ='Data Sheet'!G16 -> 44286 | I4: ='Data Sheet'!H16 -> 44651 | J4: ='Data Sheet'!I16 -> 45016 | ... L4: ='Data Sheet'!K16 -> 45747 | M4: ltm
A5: # | B5: income statement
B6: sales | C6: =IFERROR('Data Sheet'!B17,0) -> 39192.1 | D6: =IFERROR('Data Sheet'!C17,0) -> 42767.6 | E6: =IFERROR('Data Sheet'!D17,0) -> 43448.94 | F6: =IFERROR('Data Sheet'!E17,0) -> 48339.58 | G6: =IFERROR('Data Sheet'!F17,0) -> 49387.7 | H6: =IFERROR('Data Sheet'!G17,0) -> 49257.45 | I6: =IFERROR('Data Sheet'!H17,0) -> 60644.54 | J6: =IFERROR('Data Sheet'!I17,0) -> 70919.03 | ... L6: =IFERROR('Data Sheet'!K17,0) -> 75323.34 | M6: =IFERROR(SUM('Data Sheet'!B42:K42),0) -> 188374.57
B7: sales growth | C7: - | D7: =D6/C6-1 -> 0.09123012 | E7: =E6/D6-1 -> 0.015931219 | F7: =F6/E6-1 -> 0.11256063 | G7: =G6/F6-1 -> 0.021682439 | H7: =H6/G6-1 -> -0.0026372963 | I7: =I6/H6-1 -> 0.23117498 | J7: =J6/I6-1 -> 0.16942152 | K7: =K6/J6-1 -> -0.042119724 | ... M7: =M6/L6-1 -> 1.5008791
B9: COGS | C9: =IFERROR(SUM('Data Sheet'!B18,'Data Sheet'!B20:B22)-1*'Data Sheet'!B19,0) -> 19162.94 | D9: =IFERROR(SUM('Data Sheet'!C18,'Data Sheet'!C20:C22)-1*'Data Sheet'!C19,0) -> 21949.12 | E9: =IFERROR(SUM('Data Sheet'!D18,'Data Sheet'!D20:D22)-1*'Data Sheet'!D19,0) -> 21967.5 | F9: =IFERROR(SUM('Data Sheet'!E18,'Data Sheet'!E20:E22)-1*'Data Sheet'!E19,0) -> 24215.95 | G9: =IFERROR(SUM('Data Sheet'!F18,'Data Sheet'!F20:F22)-1*'Data Sheet'!F19,0) -> 24330.4 | H9: =IFERROR(SUM('Data Sheet'!G18,'Data Sheet'!G20:G22)-1*'Data Sheet'!G19,0) -> 26881.51 | I9: =IFERROR(SUM('Data Sheet'!H18,'Data Sheet'!H20:H22)-1*'Data Sheet'!H19,0) -> 34053.06 | J9: =IFERROR(SUM('Data Sheet'!I18,'Data Sheet'!I20:I22)-1*'Data Sheet'!I19,0) -> 38302.13 | ... L9: =IFERROR(SUM('Data Sheet'!K18,'Data Sheet'!K20:K22)-1*'Data Sheet'!K19,0) -> 41469.21 | M9: =IFERROR(SUM('Data Sheet'!H43:K43),0) -> 52895.65 | N9: =_xlfn.FORMULATEXT(L9) -> =IFERROR(SUM('Data Sheet'!K18,'Data Sheet'!K20:K22)-1*'Data Sheet'!K19,0)
B10: COGS % sales | C10: =C9/C6 -> 0.48894905 | D10: =D9/D6 -> 0.51321842 | E10: =E9/E6 -> 0.50559346 | F10: =F9/F6 -> 0.50095491 | G10: =G9/G6 -> 0.49264088 | H10: =H9/H6 -> 0.54573491 | I10: =I9/I6 -> 0.56151898 | J10: =J9/J6 -> 0.54008254 | ... M10: =M9/M6 -> 0.28080038
B12: gross profit | C12: =C6-C9 -> 20029.16 | D12: =D6-D9 -> 20818.48 | E12: =E6-E9 -> 21481.44 | F12: =F6-F9 -> 24123.63 | G12: =G6-G9 -> 25057.3 | H12: =H6-H9 -> 22375.94 | I12: =I6-I9 -> 26591.48 | J12: =J6-J9 -> 32616.9 | ... M12: =M6-M9 -> 135478.92
B14: selling and gernal expnences | C14: =IFERROR(SUM('Data Sheet'!B23:B24),0) -> 5497.67 | D14: =IFERROR(SUM('Data Sheet'!C23:C24),0) -> 5348.97 | E14: =IFERROR(SUM('Data Sheet'!D23:D24),0) -> 4960.85 | F14: =IFERROR(SUM('Data Sheet'!E23:E24),0) -> 5586.24 | G14: =IFERROR(SUM('Data Sheet'!F23:F24),0) -> 5713.76 | H14: =IFERROR(SUM('Data Sheet'!G23:G24),0) -> 5311.16 | I14: =IFERROR(SUM('Data Sheet'!H23:H24),0) -> 5968.33 | J14: =IFERROR(SUM('Data Sheet'!I23:I24),0) -> 6912.64 | ... L14: =IFERROR(SUM('Data Sheet'!K23:K24),0) -> 8014.68 | M14: =IFERROR('Data Sheet'!M23,0) -> 27974.07
B15: s&g exp % sales | C15: =C14/C6 -> 0.14027495 | D15: =D14/D6 -> 0.12507061 | E15: =E14/E6 -> 0.11417655 | F15: =F14/F6 -> 0.11556244 | G15: =G14/G6 -> 0.11569196 | H15: =H14/H6 -> 0.1078245 | I15: =I14/I6 -> 0.09841496 | J15: =J14/J6 -> 0.097472286 | ... M15: =M14/M6 -> 0.14850237
B17: EBITA | C17: =C12-C14 -> 14531.49 | D17: =D12-D14 -> 15469.51 | E17: =E12-E14 -> 16520.59 | F17: =F12-F14 -> 18537.39 | G17: =G12-G14 -> 19343.54 | H17: =H12-H14 -> 17064.78 | I17: =I12-I14 -> 20623.15 | J17: =J12-J14 -> 25704.26 | ... L17: =L12-L14 -> 25839.45
B18: ebit % sales | C18: =C17/C6 -> 0.370776 | D18: =D17/D6 -> 0.36171097 | E18: =E17/E6 -> 0.38022999 | F18: =F17/F6 -> 0.38348265 | G18: =G17/G6 -> 0.39166716 | H18: =H17/H6 -> 0.34644059 | I18: =I17/I6 -> 0.34006606 | J18: =J17/J6 -> 0.36244517 | ... M18: =M17/M6 -> 0
B20: Interest | C20: =IFERROR('Data Sheet'!B27,0) -> 78.13 | D20: =IFERROR('Data Sheet'!C27,0) -> 49.03 | E20: =IFERROR('Data Sheet'!D27,0) -> 115.01 | F20: =IFERROR('Data Sheet'!E27,0) -> 71.4 | G20: =IFERROR('Data Sheet'!F27,0) -> 81.38 | H20: =IFERROR('Data Sheet'!G27,0) -> 57.97 | I20: =IFERROR('Data Sheet'!H27,0) -> 59.99 | J20: =IFERROR('Data Sheet'!I27,0) -> 77.77 | ... L20: =IFERROR('Data Sheet'!K27,0) -> 45.06 | M20: =IFERROR(SUM('Data Sheet'!H27:K27),0) -> 221.93
B21: interest % sales | C21: =C20/C6 -> 0.001993514 | D21: =D20/D6 -> 0.0011464286 | E21: =E20/E6 -> 0.0026470151 | F21: =F20/F6 -> 0.0014770505 | G21: =G20/G6 -> 0.0016477787 | H21: =H20/H6 -> 0.0011768778 | I21: =I20/I6 -> 0.00098920694 | J21: =J20/J6 -> 0.0010966027 | ... M21: =M20/M6 -> 0.0011781314
B23: Depreciation | C23: =IFERROR('Data Sheet'!B26,0) -> 1077.4 | D23: =IFERROR('Data Sheet'!C26,0) -> 1152.79 | E23: =IFERROR('Data Sheet'!D26,0) -> 1236.28 | F23: =IFERROR('Data Sheet'!E26,0) -> 1396.61 | G23: =IFERROR('Data Sheet'!F26,0) -> 1644.91 | H23: =IFERROR('Data Sheet'!G26,0) -> 1645.59 | I23: =IFERROR('Data Sheet'!H26,0) -> 1732.41 | J23: =IFERROR('Data Sheet'!I26,0) -> 1809.01 | ... L23: =IFERROR('Data Sheet'!K26,0) -> 1646.32 | M23: =IFERROR(SUM('Data Sheet'!H26:K26),0) -> 6705.79
B24: Depreciation % sales | C24: =C23/C6 -> 0.027490234 | D24: =D23/D6 -> 0.026954751 | E24: =E23/E6 -> 0.028453629 | F24: =F23/F6 -> 0.028891645 | G24: =G23/G6 -> 0.033306066 | H24: =H23/H6 -> 0.033407941 | I24: =I23/I6 -> 0.028566628 | J24: =J23/J6 -> 0.025508104 | ... M24: =M23/M6 -> 0.03559817
B26: Earning before Tax | C26: =IFERROR(C17-SUM(C20,C23),0) -> 13375.96 | D26: =IFERROR(D17-SUM(D20,D23),0) -> 14267.69 | E26: =IFERROR(E17-SUM(E20,E23),0) -> 15169.3 | F26: =IFERROR(F17-SUM(F20,F23),0) -> 17069.38 | G26: =IFERROR(G17-SUM(G20,G23),0) -> 17617.25 | H26: =IFERROR(H17-SUM(H20,H23),0) -> 15361.22 | I26: =IFERROR(I17-SUM(I20,I23),0) -> 18830.75 | J26: =IFERROR(J17-SUM(J20,J23),0) -> 23817.48 | ... L26: =IFERROR(L17-SUM(L20,L23),0) -> 24148.07 | N26: =_xlfn.FORMULATEXT(L26) -> =IFERROR(L17-SUM(L20,L23),0)
B27: EBT % sales | C27: =C26/C6 -> 0.34129225 | D27: =D26/D6 -> 0.33360979 | E27: =E26/E6 -> 0.34912935 | F27: =F26/F6 -> 0.35311395 | G27: =G26/G6 -> 0.35671331 | H27: =H26/H6 -> 0.31185577 | I27: =I26/I6 -> 0.31051023 | J27: =J26/J6 -> 0.33584046 | ... M27: =M26/M6 -> 0
B29: Tax | C29: =IFERROR('Data Sheet'!B29,0) -> 5358.21 | D29: =IFERROR('Data Sheet'!C29,0) -> 5549.09 | E29: =IFERROR('Data Sheet'!D29,0) -> 5916.43 | F29: =IFERROR('Data Sheet'!E29,0) -> 6313.92 | G29: =IFERROR('Data Sheet'!F29,0) -> 4441.79 | H29: =IFERROR('Data Sheet'!G29,0) -> 4555.29 | I29: =IFERROR('Data Sheet'!H29,0) -> 5237.34 | J29: =IFERROR('Data Sheet'!I29,0) -> 6438.4 | ... L29: =IFERROR('Data Sheet'!K29,0) -> 6890.47 | M29: =IFERROR(SUM('Data Sheet'!H29:K29),0) -> 24775.67
B30: effective tax rate | C30: =C29/C6 -> 0.13671658 | D30: =D29/D6 -> 0.12974986 | E30: =E29/E6 -> 0.13616972 | F30: =F29/F6 -> 0.13061595 | G30: =G29/G6 -> 0.089937171 | H30: =H29/H6 -> 0.092479209 | I30: =I29/I6 -> 0.086361278 | J30: =J29/J6 -> 0.090785224 | ... M30: =M29/M6 -> 0.13152343
B32: Net profit | C32: =C26-C29 -> 8017.75 | D32: =D26-D29 -> 8718.6 | E32: =E26-E29 -> 9252.87 | F32: =F26-F29 -> 10755.46 | G32: =G26-G29 -> 13175.46 | H32: =H26-H29 -> 10805.93 | I32: =I26-I29 -> 13593.41 | J32: =J26-J29 -> 17379.08 | ... L32: =L26-L29 -> 17257.6
B33: Net margin | C33: =C32/C6 -> 0.20457567 | D33: =D32/D6 -> 0.20385993 | E33: =E32/E6 -> 0.21295963 | F33: =F32/F6 -> 0.222498 | G33: =G32/G6 -> 0.26677614 | H33: =H32/H6 -> 0.21937656 | I33: =I32/I6 -> 0.22414895 | J33: =J32/J6 -> 0.24505524 | ... L33: =L32/L6 -> 0.22911358
B35: No. of equity shares | C35: =IFERROR('Data Sheet'!B93,0) -> 1207.08 | D35: =IFERROR('Data Sheet'!C93,0) -> 1214.74 | E35: =IFERROR('Data Sheet'!D93,0) -> 1220.43 | F35: =IFERROR('Data Sheet'!E93,0) -> 1225.86 | G35: =IFERROR('Data Sheet'!F93,0) -> 1229.22 | H35: =IFERROR('Data Sheet'!G93,0) -> 1230.88 | I35: =IFERROR('Data Sheet'!H93,0) -> 1232.33 | J35: =IFERROR('Data Sheet'!I93,0) -> 1242.8 | ... M35: =IFERROR('Data Sheet'!L93,0) -> 0
B37: Earnings Per Shares | C37: =IFERROR(C32/C35,0) -> 6.6422689 | D37: =IFERROR(D32/D35,0) -> 7.1773384 | E37: =IFERROR(E32/E35,0) -> 7.5816475 | F37: =IFERROR(F32/F35,0) -> 8.7738078 | G37: =IFERROR(G32/G35,0) -> 10.718553 | H37: =IFERROR(H32/H35,0) -> 8.779028 | I37: =IFERROR(I32/I35,0) -> 11.030657 | J37: =IFERROR(J32/J35,0) -> 13.983811 | ... M37: =IFERROR(M32/M35,0) -> 0
B38: EPS Growh | D38: =D37/C37-1 -> 0.080555217 | E38: =E37/D37-1 -> 0.056331341 | F38: =F37/E37-1 -> 0.15724291 | G38: =G37/F37-1 -> 0.22165353 | H38: =H37/G37-1 -> -0.18095028 | I38: =I37/H37-1 -> 0.25647821 | J38: =J37/I37-1 -> 0.26772234 | K38: =K37/J37-1 -> -0.0021455732 | L38: =L37/K37-1 -> -0.011701693
B40: dividend per share | C40: =IFERROR('Data Sheet'!B31/'historical sf '!C35,0) -> 5.6666667 | D40: =IFERROR('Data Sheet'!C31/'historical sf '!D35,0) -> 4.7500041 | E40: =IFERROR('Data Sheet'!D31/'historical sf '!E35,0) -> 5.1499963 | F40: =IFERROR('Data Sheet'!E31/'historical sf '!F35,0) -> 5.7500041 | G40: =IFERROR('Data Sheet'!F31/'historical sf '!G35,0) -> 10.149998 | H40: =IFERROR('Data Sheet'!G31/'historical sf '!H35,0) -> 10.75 | I40: =IFERROR('Data Sheet'!H31/'historical sf '!I35,0) -> 11.500004 | J40: =IFERROR('Data Sheet'!I31/'historical sf '!J35,0) -> 15.5 | ... M40: =IFERROR('Data Sheet'!L31/'historical sf '!M35,0) -> 0 | N40: =_xlfn.FORMULATEXT(L40) -> =IFERROR('Data Sheet'!K31/'historical sf '!L35,0)
B41: dividend payout ratio | C41: =C40/C37 -> 0.85312214 | D41: =D40/D37 -> 0.66180579 | E41: =E40/E37 -> 0.6792714 | F41: =F40/F37 -> 0.65536016 | G41: =G40/G37 -> 0.94695593 | H41: =H40/H37 -> 1.2245091 | I41: =I40/I37 -> 1.0425493 | J41: =J40/J37 -> 1.1084246 | ... L41: =L40/L37 -> 1.0405694
B43: Retained Earning | C43: =IFERROR(IF(C37>C40,1-C41,0),0) -> 0.14687786 | D43: =IFERROR(IF(D37>D40,1-D41,0),0) -> 0.33819421 | E43: =IFERROR(IF(E37>E40,1-E41,0),0) -> 0.3207286 | F43: =IFERROR(IF(F37>F40,1-F41,0),0) -> 0.34463984 | G43: =IFERROR(IF(G37>G40,1-G41,0),0) -> 0.053044068 | H43: =IFERROR(IF(H37>H40,1-H41,0),0) -> 0 | I43: =IFERROR(IF(I37>I40,1-I41,0),0) -> 0 | J43: =IFERROR(IF(J37>J40,1-J41,0),0) -> 0 | ... M43: =IFERROR(IF(M37>M40,1-M41,0),0) -> 0 | N43: =_xlfn.FORMULATEXT(L43) -> =IFERROR(IF(L37>L40,1-L41,0),0)
A47: # | B47: Balance Sheet as on
B49: Equity Share Capital | C49: =IFERROR('Data Sheet'!B57,0) -> 804.72 | D49: =IFERROR('Data Sheet'!C57,0) -> 1214.74 | E49: =IFERROR('Data Sheet'!D57,0) -> 1220.43 | F49: =IFERROR('Data Sheet'!E57,0) -> 1225.86 | G49: =IFERROR('Data Sheet'!F57,0) -> 1229.22 | H49: =IFERROR('Data Sheet'!G57,0) -> 1230.88 | I49: =IFERROR('Data Sheet'!H57,0) -> 1232.33 | J49: =IFERROR('Data Sheet'!I57,0) -> 1242.8 | ... L49: =IFERROR('Data Sheet'!K57,0) -> 1251.41
B50: Reserves | C50: =IFERROR('Data Sheet'!B58,0) -> 41874.8 | D50: =IFERROR('Data Sheet'!C58,0) -> 45198.19 | E50: =IFERROR('Data Sheet'!D58,0) -> 51289.68 | F50: =IFERROR('Data Sheet'!E58,0) -> 57915.01 | G50: =IFERROR('Data Sheet'!F58,0) -> 64044.04 | H50: =IFERROR('Data Sheet'!G58,0) -> 59116.46 | I50: =IFERROR('Data Sheet'!H58,0) -> 61223.24 | J50: =IFERROR('Data Sheet'!I58,0) -> 67912.46 | ... L50: =IFERROR('Data Sheet'!K58,0) -> 68778.64
B51: Borrowings | C51: =IFERROR('Data Sheet'!B59,0) -> 83.78 | D51: =IFERROR('Data Sheet'!C59,0) -> 45.72 | E51: =IFERROR('Data Sheet'!D59,0) -> 35.92 | F51: =IFERROR('Data Sheet'!E59,0) -> 13.44 | G51: =IFERROR('Data Sheet'!F59,0) -> 277.45 | H51: =IFERROR('Data Sheet'!G59,0) -> 270.83 | I51: =IFERROR('Data Sheet'!H59,0) -> 249.44 | J51: =IFERROR('Data Sheet'!I59,0) -> 306.04 | ... L51: =IFERROR('Data Sheet'!K59,0) -> 284.54
B52: Other Liabilities | C52: =IFERROR('Data Sheet'!B60,0) -> 8888.04 | D52: =IFERROR('Data Sheet'!C60,0) -> 9439.67 | E52: =IFERROR('Data Sheet'!D60,0) -> 11694.85 | F52: =IFERROR('Data Sheet'!E60,0) -> 12584.73 | G52: =IFERROR('Data Sheet'!F60,0) -> 11760.04 | H52: =IFERROR('Data Sheet'!G60,0) -> 13142.59 | I52: =IFERROR('Data Sheet'!H60,0) -> 14491.01 | J52: =IFERROR('Data Sheet'!I60,0) -> 16369.66 | ... L52: =IFERROR('Data Sheet'!K60,0) -> 17688.11
B53: Total Liabilities | C53: =IFERROR('Data Sheet'!B61,0) -> 51651.34 | D53: =IFERROR('Data Sheet'!C61,0) -> 55898.32 | E53: =IFERROR('Data Sheet'!D61,0) -> 64240.88 | F53: =IFERROR('Data Sheet'!E61,0) -> 71739.04 | G53: =IFERROR('Data Sheet'!F61,0) -> 77310.75 | H53: =IFERROR('Data Sheet'!G61,0) -> 73760.76 | I53: =IFERROR('Data Sheet'!H61,0) -> 77196.02 | J53: =IFERROR('Data Sheet'!I61,0) -> 85830.96 | ... L53: =IFERROR('Data Sheet'!K61,0) -> 88002.7
B55: Net Assets | C55: =IFERROR('Data Sheet'!B62,0) -> 15106.63 | D55: =IFERROR('Data Sheet'!C62,0) -> 15893.48 | E55: =IFERROR('Data Sheet'!D62,0) -> 16523.96 | F55: =IFERROR('Data Sheet'!E62,0) -> 19374.19 | G55: =IFERROR('Data Sheet'!F62,0) -> 21713.34 | H55: =IFERROR('Data Sheet'!G62,0) -> 23298.48 | I55: =IFERROR('Data Sheet'!H62,0) -> 24231.59 | J55: =IFERROR('Data Sheet'!I62,0) -> 25851.27 | ... L55: =IFERROR('Data Sheet'!K62,0) -> 21954.85
B56: Capital Work in Progress | C56: =IFERROR('Data Sheet'!B63,0) -> 2559.72 | D56: =IFERROR('Data Sheet'!C63,0) -> 3729.89 | E56: =IFERROR('Data Sheet'!D63,0) -> 5508.33 | F56: =IFERROR('Data Sheet'!E63,0) -> 4136.42 | G56: =IFERROR('Data Sheet'!F63,0) -> 3256.46 | H56: =IFERROR('Data Sheet'!G63,0) -> 4011.29 | I56: =IFERROR('Data Sheet'!H63,0) -> 3225.54 | J56: =IFERROR('Data Sheet'!I63,0) -> 3003.3 | ... L56: =IFERROR('Data Sheet'!K63,0) -> 1090.91
B57: Investments | C57: =IFERROR('Data Sheet'!B64,0) -> 11747.59 | D57: =IFERROR('Data Sheet'!C64,0) -> 17581.38 | E57: =IFERROR('Data Sheet'!D64,0) -> 22052.86 | F57: =IFERROR('Data Sheet'!E64,0) -> 25043.49 | G57: =IFERROR('Data Sheet'!F64,0) -> 28663.35 | H57: =IFERROR('Data Sheet'!G64,0) -> 24870.87 | I57: =IFERROR('Data Sheet'!H64,0) -> 24841.01 | J57: =IFERROR('Data Sheet'!I64,0) -> 29415.02 | ... L57: =IFERROR('Data Sheet'!K64,0) -> 34719.82
B58: Other Assets | C58: =IFERROR('Data Sheet'!B65-SUM('Data Sheet'!B67:B69),0) -> 5194.82 | D58: =IFERROR('Data Sheet'!C65-SUM('Data Sheet'!C67:C69),0) -> 5135.78 | E58: =IFERROR('Data Sheet'!D65-SUM('Data Sheet'!D67:D69),0) -> 7078.75 | F58: =IFERROR('Data Sheet'!E65-SUM('Data Sheet'!E67:E69),0) -> 7138.07 | G58: =IFERROR('Data Sheet'!F65-SUM('Data Sheet'!F67:F69),0) -> 4958.45 | H58: =IFERROR('Data Sheet'!G65-SUM('Data Sheet'!G67:G69),0) -> 4022.24 | I58: =IFERROR('Data Sheet'!H65-SUM('Data Sheet'!H67:H69),0) -> 6917.41 | J58: =IFERROR('Data Sheet'!I65-SUM('Data Sheet'!I67:I69),0) -> 7953.85 | ... L58: =IFERROR('Data Sheet'!K65-SUM('Data Sheet'!K67:K69),0) -> 5867.53 | N58: =_xlfn.FORMULATEXT(L58) -> =IFERROR('Data Sheet'!K65-SUM('Data Sheet'!K67:K69),0)
B59: Total Non Current Assets | C59: =SUM(C55:C58) -> 34608.76 | D59: =SUM(D55:D58) -> 42340.53 | E59: =SUM(E55:E58) -> 51163.9 | F59: =SUM(F55:F58) -> 55692.17 | G59: =SUM(G55:G58) -> 58591.6 | H59: =SUM(H55:H58) -> 56202.88 | I59: =SUM(I55:I58) -> 59215.55 | J59: =SUM(J55:J58) -> 66223.44 | ... L59: =SUM(L55:L58) -> 63633.11
B61: Receivables | C61: =IFERROR('Data Sheet'!B67,0) -> 1917.18 | D61: =IFERROR('Data Sheet'!C67,0) -> 2474.29 | E61: =IFERROR('Data Sheet'!D67,0) -> 2682.29 | F61: =IFERROR('Data Sheet'!E67,0) -> 4035.28 | G61: =IFERROR('Data Sheet'!F67,0) -> 2562.48 | H61: =IFERROR('Data Sheet'!G67,0) -> 2501.7 | I61: =IFERROR('Data Sheet'!H67,0) -> 2461.9 | J61: =IFERROR('Data Sheet'!I67,0) -> 2956.17 | ... L61: =IFERROR('Data Sheet'!K67,0) -> 4719.67
...

Sheet fiancials>

Sheet data>
